Workbook
Name cod: tbmateriales[[#All],[CODIGO]]
Name cod: tbmateriales[[#All],[CODIGO]]
Name cod: tbmateriales[[#All],[CODIGO]]
Name cod: tbmateriales[[#All],[CODIGO]]
Name cod: tbmateriales[[#All],[CODIGO]]
Name cod: tbmateriales[[#All],[CODIGO]]
Name cod: tbmateriales[[#All],[CODIGO]]
Name cod: tbmateriales[[#All],[CODIGO]]
Name cod: tbmateriales[[#All],[CODIGO]]
Name cod: tbmateriales[[#All],[CODIGO]]
Name cod: tbmateriales[[#All],[CODIGO]]
Name cod: tbmateriales[[#All],[CODIGO]]
Name cod: tbmateriales[[#All],[CODIGO]]
Name cod: tbmateriales[[#All],[CODIGO]]
Name cod: tbmateriales[[#All],[CODIGO]]
Name cod: tbmateriales[[#All],[CODIGO]]
Name cod: tbmateriales[[#All],[CODIGO]]
Name cod: tbmateriales[[#All],[CODIGO]]
Name cod: tbmateriales[[#All],[CODIGO]]
Name cod: tbmateriales[[#All],[CODIGO]]
Name cod: tbmateriales[[#All],[CODIGO]]
Name cod: tbmateriales[[#All],[CODIGO]]
Name cod: tbmateriales[[#All],[CODIGO]]
Name cod: tbmateriales[[#All],[CODIGO]]
Name cod: tbmateriales[[#All],[CODIGO]]
Name cod: tbmateriales[[#All],[CODIGO]]
Name cod: tbmateriales[[#All],[CODIGO]]
Name cod: tbmateriales[[#All],[CODIGO]]
Name cod: tbmateriales[[#All],[CODIGO]]
Name cod: tbmateriales[[#All],[CODIGO]]
Name cod: tbmateriales[[#All],[CODIGO]]
Name cod: tbmateriales[[#All],[CODIGO]]
Name cod: tbmateriales[[#All],[CODIGO]]
Name cod: tbmateriales[[#All],[CODIGO]]
Name cod: tbmateriales[[#All],[CODIGO]]
Name cod: tbmateriales[[#All],[CODIGO]]
Name cod: tbmateriales[[#All],[CODIGO]]
Name cod: tbmateriales[[#All],[CODIGO]]
Name cod: tbmateriales[[#All],[CODIGO]]
Name cod: tbmateriales[[#All],[CODIGO]]
Name cod: tbmateriales[[#All],[CODIGO]]
Name cod: tbmateriales[[#All],[CODIGO]]
Name cod: tbmateriales[[#All],[CODIGO]]
Name cod: tbmateriales[[#All],[CODIGO]]
Name cod: tbmateriales[[#All],[CODIGO]]
Name cod: tbmateriales[[#All],[CODIGO]]
Name cod: tbmateriales[[#All],[CODIGO]]
Name cod: tbmateriales[[#All],[CODIGO]]
Name cod: tbmateriales[[#All],[CODIGO]]
Name cod: tbmateriales[[#All],[CODIGO]]
Name cod: tbmateriales[[#All],[CODIGO]]
Name cod: tbmateriales[[#All],[CODIGO]]
Name cod: tbmateriales[[#All],[CODIGO]]
Name cod: tbmateriales[[#All],[CODIGO]]
Name cod: tbmateriales[[#All],[CODIGO]]
Name cod: tbmateriales[[#All],[CODIGO]]
Name cod: tbmateriales[[#All],[CODIGO]]
Name cod: tbmateriales[[#All],[CODIGO]]
Name cod: tbmateriales[[#All],[CODIGO]]
Name cod: tbmateriales[[#All],[CODIGO]]

Sheet indice
A1: N° | B1: Clasificación | C1: Columna1 | D1: Código de Estructura | E1: Descripción | F1: Precios
A2: 1 | B2: Primaria | C2: 1F+N | D2: A-I-1 | E2: Estructura Primaria una Fase en Tangente (0º - 5º) | F2: ='A-I-1'!F10 -> 895.19
A3: 2 | B3: Primaria | C3: 1F+N | D3: A-I-1V | E3: Estructura Primaria una Fase Voladiza en Tangente (0º - 5º) | F3: ='A-I-1'!F11 -> 0
A4: 3 | B4: Primaria | C4: 1F+N | D4: A-I-2 | E4: Estructura Primaria una Fase en ángulo (5º-30º) | F4: ='A-I-1'!F12 -> 0
A5: 4 | B5: Primaria | C5: 1F+N | D5: A-I-2V | E5: Estructura Primaria una Fase Voladiza en Ángulo (0º - 5º) | F5: ='A-I-1'!F13 -> 0
A6: 5 | B6: Primaria | C6: 1F+N | D6: A-I-3 | E6: Estructura Primaria una Fase de Paso Vérttical (30º -60º) | F6: ='A-I-1'!F14 -> 0
A7: 6 | B7: Primaria | C7: 1F+N | D7: A-I-4 | E7: Estructura Primaria Una Fase en Remate. | F7: ='A-I-1'!F15 -> 0
A8: 7 | B8: Primaria | C8: 1F+N | D8: A-I-4A | E8: Estructura primaria una fase en remate a 180º de remate una fase existente. | F8: ='A-I-1'!F16 -> 0
A9: 8 | B9: Primaria | C9: 1F+N | D9: A-I-4B | E9: Estructura primaria una fase en remate, a 180º de remate existente de dos o tres fases | F9: ='A-I-1'!F17 -> 0
A10: 9 | B10: Primaria | C10: 1F+N | D10: A-I-4C | E10: Estructura primaria una fase en remate a 90º de línea de paso o remate existente. | F10: ='A-I-1'!F18 -> 0
A11: 10 | B11: Primaria | C11: 1F+N | D11: A-I-4V | E11: Estructura primaria una fase voladiza en remate | F11: ='A-I-1'!F19 -> 0
A12: 11 | B12: Primaria | C12: 1F+N | D12: A-I-5 | E12: Estructura primaria una fase en doble remate (0º-60º). | F12: ='A-I-1'!F20 -> 0
A13: 12 | B13: Primaria | C13: 1F+N | D13: A-I-5V | E13: Estructura primaria una fase voladiza en doble remate (0º-60º) | F13: ='A-I-1'!F21 -> 0
... A276: 275 | B276: Conexiones a tierra | C276: Aterrizaje | D276: CT-G | E276: Conexión Tierra a Guarda. | F276: ='A-I-1'!F284 -> 0
D277: CA-32 | E277: Control Automático de Iluminación de 32 A. | F277: ='A-I-1'!F285 -> 0
A278: 276 | B278: Luminaria | C278: Alumbrado | D278: LL-1-50W | E278: Luminaria Led Tipo Cobra 50 Watt. | F278: ='A-I-1'!F286 -> 0
A279: 277 | B279: Luminaria | C279: Alumbrado | D279: LL-1-28A-50W | E279: Luminaria Led Tipo Cobra 28 A 50 Watt. | F279: ='A-I-1'!F287 -> 0
A280: 278 | B280: Luminaria | C280: Alumbrado | D280: LL-1-100W | E280: Luminaria Led Tipo Cobra 100 Watt. | F280: ='A-I-1'!F288 -> 0
A281: 279 | B281: Luminaria | C281: Alumbrado | D281: LL-1-200W | E281: Luminaria Led Tipo Cobra 200 Watt. | F281: ='A-I-1'!F289 -> 0
B282: Logistica | C282: Horas de Grua | D282: HRSGRUA | E282: Costo de Grúa por hora. | F282: ='A-I-1'!F290 -> 0
D283: INST-LP | E283: Instalación de Línea Primaria conductor 1/0 ACSR por metro | F283: ='A-I-1'!F291 -> 0
D284: INST-LS | E284: Instalación de Línea Secundaria por metro | F284: ='A-I-1'!F292 -> 0

Sheet Materiales
A1: N° | B1: CODIGO | C1: MATERIALES | D1: Unidad | E1: REFERENCIA | F1: Costo Unitario
A2: 1 | B2: AB1 | C2: Abrazadera Doble Ajustable de 4 1/2" | D2: C/U | E2: AB CHANCE 637412 | F2: 200
A3: 2 | B3: AB2 | C3: Abrazadera Simple Ajustable de 6" | D3: C/U | E3: AB CHANCE PS6366 | F3: 200
A4: 3 | B4: AB3 | C4: Abrazadera Doble Ajustable de 6" | D4: C/U | E4: AB CHANCE PS6376 | F4: 200
A5: 4 | B5: AC | C5: Aislador de Carrete ANSI C 53-2 | D5: C/U | E5: AB CHANCE C909-1032 | F5: 15.6
A6: 5 | B6: AE1 | C6: Aislador de Espiga ANSI C 55-4 | D6: C/U | E6: AB CHANCE C905-1304 | F6: 260
A7: 6 | B7: AE2 | C7: Aislador de Espiga ANSI C 56-3 | D7: C/U | E7: AB CHANCE C906-1303 | F7: 278.88
A8: 7 | B8: AS2 | C8: Aislador de Suspensión ANSI C 52-9 | D8: C/U | E8: AB CHANCE C907-1009 | F8: 186.4
A9: 8 | B9: AS1 | C9: Aislador de Suspensión ANSI C 52-4 | D9: C/U | E9: AB CHANCE C909-1042 | F9: 140
A10: 9 | B10: ARE1 | C10: Aislador de Tensión ANSI C 54-1 | D10: C/U | E10: AB CHANCE C909-1041 | F10: 35
A11: 10 | B11: ARE2 | C11: Aislador de Tensión ANSI C 54-2 | D11: C/U | E11: AB CHANCE C909-1042 | F11: 35
A12: 11 | B12: ARE3 | C12: Aislador de Tensión ANSI C 54-3 | D12: C/U | E12: AB CHANCE C909-1043 | F12: 43.25
A13: 12 | B13: AP1 | C13: Aislador Polímero tipo Suspensión para 13.8 KV., IEC 815 | D13: C/U | E13: RAYCHEM RST-DS15R-CT | F13: 5
... A149: 148 | B149: LS6 | C149: Lámpara de Sodio de 400 Watts, Completa sin Fotocelda | D149: C/U | E149: COOPER OVX40SWW3E | F149: 5
A150: 149 | B150: LL1 | C150: Lámpara LED tipo Cobra de 50 Watts, Completa con Fotocelda | D150: C/U | F150: 1508
A151: 150 | B151: LL2 | C151: Lámpara LED tipo Cobra de 28 a 50 Watts, Completa con Fotocelda | D151: C/U | E151: Sin Referencia | F151: 5
A152: 151 | B152: LL3 | C152: Lámpara LED tipo Cobra de 100 Watts, Completa con Fotocelda | D152: C/U | E152: Sin Referencia | F152: 2500
A153: 152 | B153: LL4 | C153: Lámpara LED tipo Cobra de 200 Watts, Completa con Fotocelda | D153: C/U | E153: Sin Referencia | F153: 5
A154: 153 | B154: ME1 | C154: Medidor de Energía Electromecánico Monofásico | D154: C/U | E154: Sin Referencia | F154: 5
A155: 154 | B155: PR1 | C155: Pararrayo de Porcelana de 10 KV. | D155: C/U | E155: COOPER AZS101M010R | F155: 5
A156: 155 | B156: PR2 | C156: Pararrayo de Porcelana de 27 KV. | D156: C/U | E156: COOPER AZS101M027R | F156: 1600
A157: 156 | B157: PR3 | C157: Pararayo de Polimero para 10 KV IEEE C62.11 | D157: C/U | E157: TYCO DAH-10C, DAH-10A | F157: 5
A158: 157 | B158: PR4 | C158: Pararayo de Polimero para 27 KV IEEE C62.11 | D158: C/U | E158: TYCO DAH-27H4, DAH-27F4 | F158: 1354.82
A159: 158 | B159: PAI | C159: Perno de Acero Inoxidable 1/2" x 2" | D159: C/U | E159: BURNDY 50x200HSSB | F159: 5
A160: 159 | B160: PC | C160: Perno de Carroceria 3/8" x 5" | D160: C/U | E160: AB CHANCE 8635 | F160: 17.3
A161: 160 | B161: PM1 | C161: Perno de Máquina de 5/8" x 8" | D161: C/U | E161: AB CHANCE 8808 | F161: 24
A162: 161 | B162: PM2 | C162: Perno de Máquina de 5/8" x 10" | D162: C/U | E162: AB CHANCE 8810 | F162: 28.1
... A197: 196 | B197: PC45 | C197: Poste de Concreto de 45'. | D197: C/U | E197: Sin Referencia | F197: 14000
B198: PC50 | C198: Poste de Concreto de 50'.
A199: 197 | B199: PCA30 | C199: Poste de Concreto de 30 Pies Autosoportado. | D199: C/U | E199: Sin Referencia | F199: 13600
A200: 198 | B200: PCA35 | C200: Poste de Concreto de 35 Pies Autosoportado. | D200: C/U | E200: Sin Referencia | F200: 5
A201: 199 | B201: PCA40 | C201: Poste de Concreto de 40 Pies Autosoportado. | D201: C/U | E201: Sin Referencia | F201: 22305.22
A202: 200 | B202: PCA45 | C202: Poste de Concreto de 45 Pies Autosoportado. | D202: C/U | E202: Sin Referencia | F202: 25000
B203: PCA50 | C203: Poste de Concreto de 50 Pies Autosoportado.
A204: 201 | B204: PME30 | C204: Poste de Tubular de 30 Pies. | D204: C/U | E204: IMFICA | F204: 5
A205: 202 | B205: PME35 | C205: Poste de Tubular de 35 Pies. | D205: C/U | E205: IMFICA | F205: 5
A206: 203 | B206: PME40 | C206: Poste de Tubular de 40 Pies. | D206: C/U | E206: IMFICA | F206: 5
A207: 204 | B207: PME45 | C207: Poste de Tubular de 45 Pies. | D207: C/U | E207: IMFICA | F207: 5
B208: PCA40-2000Lb | C208: Poste de Concreto de 40 Pies Autosoportado, 2,000 Lb.
B209: PCA40-3000Lb | C209: Poste de Concreto de 40 Pies Autosoportado, 3,000 Lb.
...

Sheet Internos
A1: N° | B1: CÓDIGO | C1: DESCRIPCIÓN DE MATERIALES | D1: Unidad | E1: REFERENCIA | F1: Costo Unitario
A2: 1 | C2: THHN # 16 AWG, Rojo. | F2: 5
A3: 2 | C3: THHN # 16 AWG, Negro. | F3: 5
A4: 3 | C4: THHN # 16 AWG, Blanco. | F4: 5
A5: 4 | C5: THHN # 16 AWG, Verde. | F5: 12
A6: 5 | C6: THHN # 16 AWG, Azul. | F6: 5
A7: 6 | C7: THHN # 14 AWG, Rojo. | F7: 290
A8: 7 | C8: THHN # 14 AWG, Negro. | F8: 119
A9: 8 | C9: THHN # 14 AWG, Blanco. | F9: 5
A10: 9 | C10: THHN # 14 AWG, Verde. | F10: 5
A11: 10 | C11: THHN # 14 AWG, Azul. | F11: 5
A12: 11 | C12: THHN # 12 AWG, Rojo. | F12: 35
A13: 12 | C13: THHN # 12 AWG, Negro. | F13: 5
... A81: 80 | C81: THHN # 500 Kcmil, Azul. | F81: 5
A82: 81 | F82: 5
A83: 82 | F83: 5
A84: 83 | F84: 5
A85: 84 | F85: 5
A86: 85 | F86: 5
A87: 86 | F87: 5
A88: 87 | F88: 8.5
A89: 88 | F89: 5
A90: 89 | F90: 5
A91: 90 | F91: 11
A92: 91 | F92: 15
A93: 92 | F93: 5
... A251: 250 | F251: 225
F252: 239
F253: 255
F254: 28
F255: 250
F256: 13

Sheet conectores
A1: Calibre | B1: Código | C1: Descripción | D1: Estructuras aplicables
A2: 1/0 ACSR | B2: 25A25 | C2: CONECTOR DE COMPRESIÓN YC 25A25 (1/0-1/0) | D2: A, TM, TH, ER
A3: 1/0 ACSR | B3: 25A2 | C3: CONECTOR DE COMPRESIÓN YC 25A2 (1/0-2) | D3: A, TM, TH, ER
A4: 3/0 ACSR | B4: 28A2 | C4: CONECTOR DE COMPRESIÓN YC 28A2 (3/0-2) | D4: A, TM, TH, ER
A5: 3/0 ACSR | B5: 28A25 | C5: CONECTOR DE COMPRESIÓN YC 28A25 (3/0-1/0) | D5: A, TM, TH, ER
A6: 3/0 ACSR | B6: 28A28 | C6: CONECTOR DE COMPRESIÓN YC 28A28 (3/0-3/0) | D6: A, TM, TH, ER
A7: 266.8 MCM | B7: KDR05 | C7: CONECTOR DE COMPRESIÓN KDR05 (266.8-3/0) | D7: A, TM, TH, ER
A8: 266.8 MCM | B8: 33R28R | C8: CONECTOR DE COMPRESIÓN YPC 33R28R (266.8-2/0) | D8: A, TM, TH, ER
A9: 266.8 MCM | B9: 33R26U | C9: CONECTOR DE COMPRESIÓN YPC 33R26U (266.8-1/0) | D9: A, TM, TH, ER
A10: 266.8 MCM | B10: 33R28R | C10: CONECTOR DE COMPRESIÓN YPC 33R28R (266.8-3/0) | D10: A, TM, TH, ER
A11: 266.8 MCM | B11: 26R8U | C11: CONECTOR DE COMPRESIÓN YPC 26R8U | D11: A, TM, TH, ER
A12: 266.8 MCM | B12: 33R33R | C12: CONECTOR DE COMPRESIÓN YPC 33R33R (266.8-266.8) | D12: A, TM, TH, ER

Sheet PM-30
A1: COD. ENEE | B1: Materiales | C1: Unidad | D1: 34.5 | E1: 13.8 | F1: Precio
A2: PM30 | B2: =VLOOKUP(A2,tmat,2,FALSE) -> Poste de Madera de 30' | C2: C/U | D2: 1 | E2: 1 | F2: =VLOOKUP(A2, Materiales!B:F, 5, FALSE) -> 6700
E3: Total | F3: =SUM(F2) -> 6700

Sheet PM-35
A1: COD. ENEE | B1: Materiales | C1: Unidad | D1: 34.5 | E1: 13.8
A2: PM35 | B2: =VLOOKUP(A2,tmat,2,FALSE) -> Poste de Madera de 35' | C2: C/U | D2: 1 | E2: 1

Sheet PM-40
A1: COD. ENEE | B1: Materiales | C1: Unidad | D1: 34.5 | E1: 13.8
A2: PM40 | B2: =VLOOKUP(A2,tmat,2,FALSE) -> Poste de Madera de 40' | C2: C/U | D2: 1 | E2: 1

Sheet PM-45
A1: COD. ENEE | B1: Materiales | C1: Unidad | D1: 34.5 | E1: 13.8
A2: PM45 | B2: =VLOOKUP(A2,tmat,2,FALSE) -> Poste de Madera de 45' | C2: C/U | D2: 1 | E2: 1

Sheet PC-30
A1: COD. ENEE | B1: Materiales | C1: Unidad | D1: 34.5 | E1: 13.8
A2: PC30 | B2: =VLOOKUP(A2,tmat,2,FALSE) -> Poste de Concreto de 30'. | C2: C/U | D2: 1 | E2: 1

Sheet PC-40
A1: COD. ENEE | B1: Materiales | C1: Unidad | D1: 34.5 | E1: 13.8
A2: PC40 | B2: =VLOOKUP(A2,tmat,2,FALSE) -> Poste de Concreto de 40'. | C2: C/U | D2: 1 | E2: 1

Sheet PC-45
A1: COD. ENEE | B1: Materiales | C1: Unidad | D1: 34.5 | E1: 13.8
A2: PC45 | B2: =VLOOKUP(A2,tmat,2,FALSE) -> Poste de Concreto de 45'. | C2: C/U | D2: 1 | E2: 1

Sheet PC-50
A1: COD. ENEE | B1: Materiales | C1: Unidad | D1: 34.5 | E1: 13.8
A2: PC50 | B2: =VLOOKUP(A2,tmat,2,FALSE) -> Poste de Concreto de 50'. | C2: C/U | D2: 1 | E2: 1

Sheet PCA-30
A1: COD. ENEE | B1: Materiales | C1: Unidad | D1: 34.5 | E1: 13.8
A2: PCA30 | B2: =VLOOKUP(A2,tmat,2,FALSE) -> Poste de Concreto de 30 Pies Autosoportado. | C2: C/U | D2: 1 | E2: 1

Sheet PCA-35
A1: COD. ENEE | B1: Materiales | C1: Unidad | D1: 34.5 | E1: 13.8
A2: PCA35 | B2: =VLOOKUP(A2,tmat,2,FALSE) -> Poste de Concreto de 35 Pies Autosoportado. | C2: C/U | D2: 1 | E2: 1

Sheet PCA-40
A1: COD. ENEE | B1: Materiales | C1: Unidad | D1: 34.5 | E1: 13.8
A2: PCA40 | B2: =VLOOKUP(A2,tmat,2,FALSE) -> Poste de Concreto de 40 Pies Autosoportado. | C2: C/U | D2: 1 | E2: 1

Sheet PCA-45
A1: COD. ENEE | B1: Materiales | C1: Unidad | D1: 34.5 | E1: 13.8
A2: PCA45 | B2: =VLOOKUP(A2,tmat,2,FALSE) -> Poste de Concreto de 45 Pies Autosoportado. | C2: C/U | D2: 1 | E2: 1

Sheet PCA-50
A1: COD. ENEE | B1: Materiales | C1: Unidad | D1: 34.5 | E1: 13.8
A2: PCA50 | B2: =VLOOKUP(A2,tmat,2,FALSE) -> Poste de Concreto de 50 Pies Autosoportado. | C2: C/U | D2: 1 | E2: 1

Sheet PT-30
A1: COD. ENEE | B1: Materiales | C1: Unidad | D1: 34.5 | E1: 13.8
A2: PME30 | B2: =VLOOKUP(A2,tmat,2,FALSE) -> Poste de Tubular de 30 Pies. | C2: C/U | D2: 1 | E2: 1

Sheet PT-35
A1: COD. ENEE | B1: Materiales | C1: Unidad | D1: 34.5 | E1: 13.8
A2: PME35 | B2: =VLOOKUP(A2,tmat,2,FALSE) -> Poste de Tubular de 35 Pies. | C2: C/U | D2: 1 | E2: 1

Sheet PT-40
A1: COD. ENEE | B1: Materiales | C1: Unidad | D1: 34.5 | E1: 13.8
A2: PME40 | B2: =VLOOKUP(A2,tmat,2,FALSE) -> Poste de Tubular de 40 Pies. | C2: C/U | D2: 1 | E2: 1

Sheet PT-45
A1: COD. ENEE | B1: Materiales | C1: Unidad | D1: 34.5 | E1: 13.8
A2: PME45 | B2: =VLOOKUP(A2,tmat,2,FALSE) -> Poste de Tubular de 45 Pies. | C2: C/U | D2: 1 | E2: 1

Sheet PCA-40-2000Lb
A1: COD. ENEE | B1: Materiales | C1: Unidad | D1: 34.5 | E1: 13.8
A2: PCA40-2000Lb | B2: =VLOOKUP(A2,tmat,2,FALSE) -> Poste de Concreto de 40 Pies Autosoportado, 2,000 Lb. | C2: C/U | D2: 1 | E2: 1

Sheet PCA-40-3000Lb
A1: COD. ENEE | B1: Materiales | C1: Unidad | D1: 34.5 | E1: 13.8
A2: PCA40-3000Lb | B2: =VLOOKUP(A2,tmat,2,FALSE) -> Poste de Concreto de 40 Pies Autosoportado, 3,000 Lb. | C2: C/U | D2: 1 | E2: 1

Sheet PCA-45-2000Lb
A1: COD. ENEE | B1: Materiales | C1: Unidad | D1: 34.5 | E1: 13.8
A2: PCA45-2000Lb | B2: =VLOOKUP(A2,tmat,2,FALSE) -> Poste de Concreto de 45 Pies Autosoportado, 2,000 Lb. | C2: C/U | D2: 1 | E2: 1

Sheet PCA-45-3000Lb
A1: COD. ENEE | B1: Materiales | C1: Unidad | D1: 34.5 | E1: 13.8
A2: PCA45-3000Lb | B2: =VLOOKUP(A2,tmat,2,FALSE) -> Poste de Concreto de 45 Pies Autosoportado, 3,000 Lb. | C2: C/U | D2: 1 | E2: 1

Sheet PCA-50-2000Lb
A1: COD. ENEE | B1: Materiales | C1: Unidad | D1: 34.5 | E1: 13.8
A2: PCA50-2000Lb | B2: =VLOOKUP(A2,tmat,2,FALSE) -> Poste de Concreto de 50 Pies Autosoportado, 2,000 Lb. | C2: C/U | D2: 1 | E2: 1

Sheet PC-50-3000Lb
A1: COD. ENEE | B1: Materiales | C1: Unidad | D1: 34.5 | E1: 13.8
A2: PCA50-3000Lb | B2: =VLOOKUP(A2,tmat,2,FALSE) -> Poste de Concreto de 50 Pies Autosoportado, 3,000 Lb. | C2: C/U | D2: 1 | E2: 1

Sheet A-I-1
A1: COD. ENEE | B1: Materiales | C1: Unidad | D1: 34.5 | E1: 13.8 | F1: Precios
A2: AE1 | B2: =VLOOKUP(A2,tmat,2,FALSE) -> Aislador de Espiga ANSI C 55-4 | C2: C/U | D2: 0 | E2: 1 | F2: =VLOOKUP(A2, Materiales!B:F, 5, FALSE) -> 260
A3: AE2 | B3: =VLOOKUP(A3,tmat,2,FALSE) -> Aislador de Espiga ANSI C 56-3 | C3: C/U | D3: 1 | E3: 0 | F3: =VLOOKUP(A3, Materiales!B:F, 5, FALSE) -> 278.88
A4: AA1 | B4: =VLOOKUP(A4,tmat,2,FALSE) -> Alambre de Amarre N° 6 | C4: Pie | D4: 10 | E4: 10 | F4: =VLOOKUP(A4, Materiales!B:F, 5, FALSE) -> 2.17
A5: AR1 | B5: =VLOOKUP(A5,tmat,2,FALSE) -> Arandela Cuadrada 3/16" x 2-1/4" x 2-1/4", Ø=11/16" | C5: C/U | D5: 2 | E5: 2 | F5: =VLOOKUP(A5, Materiales!B:F, 5, FALSE) -> 10.37
A6: EP2 | B6: =VLOOKUP(A6,tmat,2,FALSE) -> Espiga Punta de Poste tipo Recta, 34.5 KV, L=20" Rosca 1-3/8" | C6: C/U | D6: 1 | E6: 0 | F6: =VLOOKUP(A6, Materiales!B:F, 5, FALSE) -> 153.85
A7: EP1 | B7: =VLOOKUP(A7,tmat,2,FALSE) -> Espiga Punta de Poste tipo Recta, 13.8 KV, L=18" Rosca 1" | C7: C/U | D7: 0 | E7: 1 | F7: =VLOOKUP(A7, Materiales!B:F, 5, FALSE) -> 5
A8: PM2 | B8: =VLOOKUP(A8,tmat,2,FALSE) -> Perno de Máquina de 5/8" x 10" | C8: C/U | D8: 2 | E8: 2 | F8: =VLOOKUP(A8, Materiales!B:F, 5, FALSE) -> 28.1
A9: VAP2 | B9: =VLOOKUP(A9,tmat,2,FALSE) -> Varilla de Armar Preformado para Cable ASCR # 1/0 AWG | C9: C/U | D9: 1 | E9: 1 | F9: =VLOOKUP(A9, Materiales!B:F, 5, FALSE) -> 156.82
F10: =SUM(F2:F9) -> 895.19

Sheet A-I-1V
A1: COD. ENEE | B1: Materiales | C1: Unidad | D1: 34.5 | E1: 13.8
A2: AE1 | B2: =VLOOKUP(A2,tmat,2,FALSE) -> Aislador de Espiga ANSI C 55-4 | C2: C/U | D2: 0 | E2: 1
A3: AE2 | B3: =VLOOKUP(A3,tmat,2,FALSE) -> Aislador de Espiga ANSI C 56-3 | C3: C/U | D3: 1 | E3: 0
A4: AA1 | B4: =VLOOKUP(A4,tmat,2,FALSE) -> Alambre de Amarre N° 6 | C4: Pie | D4: 10 | E4: 10
A5: AR1 | B5: =VLOOKUP(A5,tmat,2,FALSE) -> Arandela Cuadrada 3/16" x 2-1/4" x 2-1/4", Ø=11/16" | C5: C/U | D5: 3 | E5: 3
A6: CR3 | B6: =VLOOKUP(A6,tmat,2,FALSE) -> Crucete de Madera Curada de 4" x 5" x 96" /Voladizo | C6: C/U | D6: 1 | E6: 1
A7: EC1 | B7: =VLOOKUP(A7,tmat,2,FALSE) -> Espiga para Cruceta de Madera, L=6" Rosca 1", Φ = 3/4" | C7: C/U | D7: 1 | E7: 0
A8: EC2 | B8: =VLOOKUP(A8,tmat,2,FALSE) -> Espiga para Cruceta de Madera, L=8" Rosca 1-3/8", Φ = 3/4" | C8: C/U | D8: 0 | E8: 1
A9: PM1 | B9: =VLOOKUP(A9,tmat,2,FALSE) -> Perno de Máquina de 5/8" x 8" | C9: C/U | D9: 1 | E9: 1
A10: PM4 | B10: =VLOOKUP(A10,tmat,2,FALSE) -> Perno de Máquina de 5/8" x 14" | C10: C/U | D10: 1 | E10: 1
A11: PAN1 | B11: =VLOOKUP(A11,tmat,2,FALSE) -> Puntal Angular de 60", 1-3/4" x 1-3/4" x 3/16" | C11: C/U | D11: 1 | E11: 1
A12: PM10 | B12: =VLOOKUP(A12,tmat,2,FALSE) -> Perno de Máquina de 1/2" x 10" | C12: C/U | D12: 1 | E12: 1
A13: VAP2 | B13: =VLOOKUP(A13,tmat,2,FALSE) -> Varilla de Armar Preformado para Cable ASCR # 1/0 AWG | C13: C/U | D13: 1 | E13: 1

Sheet A-I-2
A1: COD. ENEE | B1: Materiales | C1: Unidad | D1: 34.5 | E1: 13.8
A2: AE1 | B2: =VLOOKUP(A2,tmat,2,FALSE) -> Aislador de Espiga ANSI C 55-4 | C2: C/U | D2: 0 | E2: 2
A3: AE2 | B3: =VLOOKUP(A3,tmat,2,FALSE) -> Aislador de Espiga ANSI C 56-3 | C3: C/U | D3: 2 | E3: 0
A4: AA1 | B4: =VLOOKUP(A4,tmat,2,FALSE) -> Alambre de Amarre N° 6 | C4: Pie | D4: 10 | E4: 10
A5: AR1 | B5: =VLOOKUP(A5,tmat,2,FALSE) -> Arandela Cuadrada 3/16" x 2-1/4" x 2-1/4", Ø=11/16" | C5: C/U | D5: 2 | E5: 2
A6: EP1 | B6: =VLOOKUP(A6,tmat,2,FALSE) -> Espiga Punta de Poste tipo Recta, 13.8 KV, L=18" Rosca 1" | C6: C/U | D6: 0 | E6: 2
A7: EPC | B7: =VLOOKUP(A7,tmat,2,FALSE) -> Espiga para Punta de Poste tipo Escuadra, 34.5 KV, L=21" Rosca 1-3/8" | C7: C/U | D7: 2 | E7: 0
A8: PM3 | B8: =VLOOKUP(A8,tmat,2,FALSE) -> Perno de Máquina de 5/8" x 12" | C8: C/U | D8: 2 | E8: 2
A9: VAP2 | B9: =VLOOKUP(A9,tmat,2,FALSE) -> Varilla de Armar Preformado para Cable ASCR # 1/0 AWG | C9: C/U | D9: 1 | E9: 1

Sheet A-I-4
A1: COD. ENEE | B1: Materiales | C1: Unidad | D1: 34.5 | E1: 13.8
A2: AS2 | B2: =VLOOKUP(A2,tmat,2,FALSE) -> Aislador de Suspensión ANSI C 52-9 | C2: C/U | D2: 3 | E2: 2
A3: AR1 | B3: =VLOOKUP(A3,tmat,2,FALSE) -> Arandela Cuadrada 3/16" x 2-1/4" x 2-1/4", Ø=11/16" | C3: C/U | D3: 2 | E3: 2
A4: GT4 | B4: =VLOOKUP(A4,tmat,2,FALSE) -> Grapa Terminal tipo Recto para Conductor (1/0 - 4/0) | C4: C/U | D4: 1 | E4: 1
A5: PRC1 | B5: =VLOOKUP(A5,tmat,2,FALSE) -> Perno de Rosca Corrida 5/8" x 12" | C5: C/U | D5: 1 | E5: 1
A6: TO1 | B6: =VLOOKUP(A6,tmat,2,FALSE) -> Tuerca de Ojo de 5/8" | C6: C/U | D6: 1 | E6: 1

Sheet A-I-4A
A1: COD. ENEE | B1: Materiales | C1: Unidad | D1: 34.5 | E1: 13.8
A2: AS2 | B2: =VLOOKUP(A2,tmat,2,FALSE) -> Aislador de Suspensión ANSI C 52-9 | C2: C/U | D2: 3 | E2: 2
A3: AE1 | B3: =VLOOKUP(A3,tmat,2,FALSE) -> Aislador de Espiga ANSI C 55-4 | C3: C/U | D3: 0 | E3: 1
A4: AE2 | B4: =VLOOKUP(A4,tmat,2,FALSE) -> Aislador de Espiga ANSI C 56-3 | C4: C/U | D4: 1 | E4: 0
A5: AA1 | B5: =VLOOKUP(A5,tmat,2,FALSE) -> Alambre de Amarre N° 6 | C5: Pie | D5: 5 | E5: 5
A6: AR1 | B6: =VLOOKUP(A6,tmat,2,FALSE) -> Arandela Cuadrada 3/16" x 2-1/4" x 2-1/4", Ø=11/16" | C6: C/U | D6: 2 | E6: 2
A7: CC2 | B7: =VLOOKUP(A7,tmat,2,FALSE) -> Conector de Compresión YC 25A25 (1/0-1/0) | C7: C/U | D7: 1 | E7: 1
A8: EP2 | B8: =VLOOKUP(A8,tmat,2,FALSE) -> Espiga Punta de Poste tipo Recta, 34.5 KV, L=20" Rosca 1-3/8" | C8: C/U | D8: 1 | E8: 0
A9: EP1 | B9: =VLOOKUP(A9,tmat,2,FALSE) -> Espiga Punta de Poste tipo Recta, 13.8 KV, L=18" Rosca 1" | C9: C/U | D9: 0 | E9: 1
A10: GT4 | B10: =VLOOKUP(A10,tmat,2,FALSE) -> Grapa Terminal tipo Recto para Conductor (1/0 - 4/0) | C10: C/U | D10: 1 | E10: 1
A11: PM2 | B11: =VLOOKUP(A11,tmat,2,FALSE) -> Perno de Máquina de 5/8" x 10" | C11: C/U | D11: 2 | E11: 2
A12: TO1 | B12: =VLOOKUP(A12,tmat,2,FALSE) -> Tuerca de Ojo de 5/8" | C12: C/U | D12: 1 | E12: 1

Sheet A-I-4B
A1: COD. ENEE | B1: Materiales | C1: Unidad | D1: 34.5 | E1: 13.8
A2: AE1 | B2: =VLOOKUP(A2,tmat,2,FALSE) -> Aislador de Espiga ANSI C 55-4 | C2: C/U | D2: 1 | E2: 0
A3: AE2 | B3: =VLOOKUP(A3,tmat,2,FALSE) -> Aislador de Espiga ANSI C 56-3 | C3: C/U | D3: 1 | E3: 0
A4: AS2 | B4: =VLOOKUP(A4,tmat,2,FALSE) -> Aislador de Suspensión ANSI C 52-9 | C4: C/U | D4: 3 | E4: 2
A5: AA1 | B5: =VLOOKUP(A5,tmat,2,FALSE) -> Alambre de Amarre N° 6 | C5: Pie | D5: 5 | E5: 5
A6: CC2 | B6: =VLOOKUP(A6,tmat,2,FALSE) -> Conector de Compresión YC 25A25 (1/0-1/0) | C6: C/U | D6: 1 | E6: 1
A7: EC1 | B7: =VLOOKUP(A7,tmat,2,FALSE) -> Espiga para Cruceta de Madera, L=6" Rosca 1", Φ = 3/4" | C7: C/U | D7: 0 | E7: 1
A8: EC2 | B8: =VLOOKUP(A8,tmat,2,FALSE) -> Espiga para Cruceta de Madera, L=8" Rosca 1-3/8", Φ = 3/4" | C8: C/U | D8: 1 | E8: 0
A9: GT4 | B9: =VLOOKUP(A9,tmat,2,FALSE) -> Grapa Terminal tipo Recto para Conductor (1/0 - 4/0) | C9: C/U | D9: 1 | E9: 1
A10: TO1 | B10: =VLOOKUP(A10,tmat,2,FALSE) -> Tuerca de Ojo de 5/8" | C10: C/U | D10: 1 | E10: 1

Sheet A-I-4C
A1: COD. ENEE | B1: Materiales | C1: Unidad | D1: 34.5 | E1: 13.8
A2: AS2 | B2: =VLOOKUP(A2,tmat,2,FALSE) -> Aislador de Suspensión ANSI C 52-9 | C2: C/U | D2: 3 | E2: 2
A3: AR1 | B3: =VLOOKUP(A3,tmat,2,FALSE) -> Arandela Cuadrada 3/16" x 2-1/4" x 2-1/4", Ø=11/16" | C3: C/U | D3: 2 | E3: 2
A4: CC2 | B4: =VLOOKUP(A4,tmat,2,FALSE) -> Conector de Compresión YC 25A25 (1/0-1/0) | C4: C/U | D4: 1 | E4: 1
A5: GT4 | B5: =VLOOKUP(A5,tmat,2,FALSE) -> Grapa Terminal tipo Recto para Conductor (1/0 - 4/0) | C5: C/U | D5: 1 | E5: 1
A6: PRC1 | B6: =VLOOKUP(A6,tmat,2,FALSE) -> Perno de Rosca Corrida 5/8" x 12" | C6: C/U | D6: 1 | E6: 1
A7: TO1 | B7: =VLOOKUP(A7,tmat,2,FALSE) -> Tuerca de Ojo de 5/8" | C7: C/U | D7: 1 | E7: 1

Sheet A-I-4V
A1: COD. ENEE | B1: Materiales | C1: Unidad | D1: 34.5 | E1: 13.8
A2: AS2 | B2: =VLOOKUP(A2,tmat,2,FALSE) -> Aislador de Suspensión ANSI C 52-9 | C2: C/U | D2: 3 | E2: 2
A3: AR1 | B3: =VLOOKUP(A3,tmat,2,FALSE) -> Arandela Cuadrada 3/16" x 2-1/4" x 2-1/4", Ø=11/16" | C3: C/U | D3: 12 | E3: 12
A4: CR3 | B4: =VLOOKUP(A4,tmat,2,FALSE) -> Crucete de Madera Curada de 4" x 5" x 96" /Voladizo | C4: C/U | D4: 2 | E4: 2
A5: GT4 | B5: =VLOOKUP(A5,tmat,2,FALSE) -> Grapa Terminal tipo Recto para Conductor (1/0 - 4/0) | C5: C/U | D5: 1 | E5: 1
A6: PM1 | B6: =VLOOKUP(A6,tmat,2,FALSE) -> Perno de Máquina de 5/8" x 8" | C6: C/U | D6: 2 | E6: 2
A7: PRC5 | B7: =VLOOKUP(A7,tmat,2,FALSE) -> Perno de Rosca Corrida 5/8" x 20" | C7: C/U | D7: 3 | E7: 3
A8: PAN1 | B8: =VLOOKUP(A8,tmat,2,FALSE) -> Puntal Angular de 60", 1-3/4" x 1-3/4" x 3/16" | C8: C/U | D8: 2 | E8: 2
A9: PM10 | B9: =VLOOKUP(A9,tmat,2,FALSE) -> Perno de Máquina de 1/2" x 10" | C9: C/U | D9: 2 | E9: 2
A10: TO1 | B10: =VLOOKUP(A10,tmat,2,FALSE) -> Tuerca de Ojo de 5/8" | C10: C/U | D10: 1 | E10: 1

Sheet A-I-5
A1: COD. ENEE | B1: Materiales | C1: Unidad | D1: 34.5 | E1: 13.8
A2: AE1 | B2: =VLOOKUP(A2,tmat,2,FALSE) -> Aislador de Espiga ANSI C 55-4 | C2: C/U | D2: 0 | E2: 1
A3: AE2 | B3: =VLOOKUP(A3,tmat,2,FALSE) -> Aislador de Espiga ANSI C 56-3 | C3: C/U | D3: 1 | E3: 0
A4: AS2 | B4: =VLOOKUP(A4,tmat,2,FALSE) -> Aislador de Suspensión ANSI C 52-9 | C4: C/U | D4: 6 | E4: 4
A5: AA1 | B5: =VLOOKUP(A5,tmat,2,FALSE) -> Alambre de Amarre N° 6 | C5: Pie | D5: 5 | E5: 5
A6: AR1 | B6: =VLOOKUP(A6,tmat,2,FALSE) -> Arandela Cuadrada 3/16" x 2-1/4" x 2-1/4", Ø=11/16" | C6: C/U | D6: 4 | E6: 4
A7: CC2 | B7: =VLOOKUP(A7,tmat,2,FALSE) -> Conector de Compresión YC 25A25 (1/0-1/0) | C7: C/U | D7: 1 | E7: 1
A8: EP2 | B8: =VLOOKUP(A8,tmat,2,FALSE) -> Espiga Punta de Poste tipo Recta, 34.5 KV, L=20" Rosca 1-3/8" | C8: C/U | D8: 1 | E8: 0
A9: EP1 | B9: =VLOOKUP(A9,tmat,2,FALSE) -> Espiga Punta de Poste tipo Recta, 13.8 KV, L=18" Rosca 1" | C9: C/U | D9: 0 | E9: 1
A10: GT4 | B10: =VLOOKUP(A10,tmat,2,FALSE) -> Grapa Terminal tipo Recto para Conductor (1/0 - 4/0) | C10: C/U | D10: 2 | E10: 2
A11: PM2 | B11: =VLOOKUP(A11,tmat,2,FALSE) -> Perno de Máquina de 5/8" x 10" | C11: C/U | D11: 2 | E11: 2
A12: PRC1 | B12: =VLOOKUP(A12,tmat,2,FALSE) -> Perno de Rosca Corrida 5/8" x 12" | C12: C/U | D12: 1 | E12: 1
A13: TO1 | B13: =VLOOKUP(A13,tmat,2,FALSE) -> Tuerca de Ojo de 5/8" | C13: C/U | D13: 2 | E13: 2

Sheet A-I-5V
A1: COD.ENEE | B1: MATERIALES | C1: UNIDAD | D1: 34.5 kV | E1: 13.8 kV
A2: AA1 | B2: =VLOOKUP(A2,tmat,2,FALSE) -> Alambre de Amarre N° 6 | C2: Pie | D2: 5 | E2: 5
A3: AE1 | B3: =VLOOKUP(A3,tmat,2,FALSE) -> Aislador de Espiga ANSI C 55-4 | C3: C/U | D3: 0 | E3: 1
A4: AE2 | B4: =VLOOKUP(A4,tmat,2,FALSE) -> Aislador de Espiga ANSI C 56-3 | C4: C/U | D4: 1 | E4: 0
A5: AS2 | B5: =VLOOKUP(A5,tmat,2,FALSE) -> Aislador de Suspensión ANSI C 52-9 | C5: C/U | D5: 6 | E5: 4
A6: AR1 | B6: =VLOOKUP(A6,tmat,2,FALSE) -> Arandela Cuadrada 3/16" x 2-1/4" x 2-1/4", Ø=11/16" | C6: C/U | D6: 12 | E6: 12
A7: CC2 | B7: =VLOOKUP(A7,tmat,2,FALSE) -> Conector de Compresión YC 25A25 (1/0-1/0) | C7: C/U | D7: 1 | E7: 1
A8: CR3 | B8: =VLOOKUP(A8,tmat,2,FALSE) -> Crucete de Madera Curada de 4" x 5" x 96" /Voladizo | C8: C/U | D8: 2 | E8: 2
A9: EC1 | B9: =VLOOKUP(A9,tmat,2,FALSE) -> Espiga para Cruceta de Madera, L=6" Rosca 1", Φ = 3/4" | C9: C/U | D9: 0 | E9: 1
A10: EC2 | B10: =VLOOKUP(A10,tmat,2,FALSE) -> Espiga para Cruceta de Madera, L=8" Rosca 1-3/8", Φ = 3/4" | C10: C/U | D10: 1 | E10: 0
A11: GT4 | B11: =VLOOKUP(A11,tmat,2,FALSE) -> Grapa Terminal tipo Recto para Conductor (1/0 - 4/0) | C11: C/U | D11: 2 | E11: 2
A12: PM1 | B12: =VLOOKUP(A12,tmat,2,FALSE) -> Perno de Máquina de 5/8" x 8" | C12: C/U | D12: 2 | E12: 2
A13: PRC5 | B13: =VLOOKUP(A13,tmat,2,FALSE) -> Perno de Rosca Corrida 5/8" x 20" | C13: C/U | D13: 3 | E13: 3
... A16: TO1 | B16: =VLOOKUP(A16,tmat,2,FALSE) -> Tuerca de Ojo de 5/8" | C16: C/U | D16: 2 | E16: 2

Sheet A-I-6
A1: COD. ENEE | B1: Materiales | C1: Unidad | D1: 34.5 | E1: 13.8
A2: AS2 | B2: =VLOOKUP(A2,tmat,2,FALSE) -> Aislador de Suspensión ANSI C 52-9 | C2: C/U | D2: 6 | E2: 4
A3: AR1 | B3: =VLOOKUP(A3,tmat,2,FALSE) -> Arandela Cuadrada 3/16" x 2-1/4" x 2-1/4", Ø=11/16" | C3: C/U | D3: 4 | E3: 4
A4: CC2 | B4: =VLOOKUP(A4,tmat,2,FALSE) -> Conector de Compresión YC 25A25 (1/0-1/0) | C4: C/U | D4: 1 | E4: 1
A5: GT4 | B5: =VLOOKUP(A5,tmat,2,FALSE) -> Grapa Terminal tipo Recto para Conductor (1/0 - 4/0) | C5: C/U | D5: 2 | E5: 2
A6: PRC1 | B6: =VLOOKUP(A6,tmat,2,FALSE) -> Perno de Rosca Corrida 5/8" x 12" | C6: C/U | D6: 2 | E6: 2
A7: TO1 | B7: =VLOOKUP(A7,tmat,2,FALSE) -> Tuerca de Ojo de 5/8" | C7: C/U | D7: 2 | E7: 2

Sheet A-I-7
A1: COD. ENEE | B1: Materiales | C1: Unidad | D1: 34.5 | E1: 13.8
A2: AE1 | B2: =VLOOKUP(A2,tmat,2,FALSE) -> Aislador de Espiga ANSI C 55-4 | C2: C/U | D2: 0 | E2: 1
A3: AE2 | B3: =VLOOKUP(A3,tmat,2,FALSE) -> Aislador de Espiga ANSI C 56-3 | C3: C/U | D3: 1 | E3: 0
A4: AS2 | B4: =VLOOKUP(A4,tmat,2,FALSE) -> Aislador de Suspensión ANSI C 52-9 | C4: C/U | D4: 3 | E4: 2
A5: AA1 | B5: =VLOOKUP(A5,tmat,2,FALSE) -> Alambre de Amarre N° 6 | C5: Pie | D5: 10 | E5: 10
A6: AR1 | B6: =VLOOKUP(A6,tmat,2,FALSE) -> Arandela Cuadrada 3/16" x 2-1/4" x 2-1/4", Ø=11/16" | C6: C/U | D6: 4 | E6: 4
A7: CC2 | B7: =VLOOKUP(A7,tmat,2,FALSE) -> Conector de Compresión YC 25A25 (1/0-1/0) | C7: C/U | D7: 1 | E7: 1
A8: EP2 | B8: =VLOOKUP(A8,tmat,2,FALSE) -> Espiga Punta de Poste tipo Recta, 34.5 KV, L=20" Rosca 1-3/8" | C8: C/U | D8: 1 | E8: 0
A9: EP1 | B9: =VLOOKUP(A9,tmat,2,FALSE) -> Espiga Punta de Poste tipo Recta, 13.8 KV, L=18" Rosca 1" | C9: C/U | D9: 0 | E9: 1
A10: GT4 | B10: =VLOOKUP(A10,tmat,2,FALSE) -> Grapa Terminal tipo Recto para Conductor (1/0 - 4/0) | C10: C/U | D10: 1 | E10: 1
A11: PM2 | B11: =VLOOKUP(A11,tmat,2,FALSE) -> Perno de Máquina de 5/8" x 10" | C11: C/U | D11: 2 | E11: 2
A12: PRC1 | B12: =VLOOKUP(A12,tmat,2,FALSE) -> Perno de Rosca Corrida 5/8" x 12" | C12: C/U | D12: 1 | E12: 1
A13: TO1 | B13: =VLOOKUP(A13,tmat,2,FALSE) -> Tuerca de Ojo de 5/8" | C13: C/U | D13: 1 | E13: 1
A14: VAP2 | B14: =VLOOKUP(A14,tmat,2,FALSE) -> Varilla de Armar Preformado para Cable ASCR # 1/0 AWG | C14: C/U | D14: 1 | E14: 1

Sheet A-I-7V
A1: COD. ENEE | B1: Materiales | C1: Unidad | D1: 34.5 | E1: 13.8
A2: AE1 | B2: =VLOOKUP(A2,tmat,2,FALSE) -> Aislador de Espiga ANSI C 55-4 | C2: C/U | D2: 0 | E2: 1
A3: AE2 | B3: =VLOOKUP(A3,tmat,2,FALSE) -> Aislador de Espiga ANSI C 56-3 | C3: C/U | D3: 1 | E3: 0
A4: AS2 | B4: =VLOOKUP(A4,tmat,2,FALSE) -> Aislador de Suspensión ANSI C 52-9 | C4: C/U | D4: 3 | E4: 2
A5: AA1 | B5: =VLOOKUP(A5,tmat,2,FALSE) -> Alambre de Amarre N° 6 | C5: Pie | D5: 10 | E5: 10
A6: AR1 | B6: =VLOOKUP(A6,tmat,2,FALSE) -> Arandela Cuadrada 3/16" x 2-1/4" x 2-1/4", Ø=11/16" | C6: C/U | D6: 5 | E6: 5
A7: CR3 | B7: =VLOOKUP(A7,tmat,2,FALSE) -> Crucete de Madera Curada de 4" x 5" x 96" /Voladizo | C7: C/U | D7: 1 | E7: 1
A8: EC1 | B8: =VLOOKUP(A8,tmat,2,FALSE) -> Espiga para Cruceta de Madera, L=6" Rosca 1", Φ = 3/4" | C8: C/U | D8: 0 | E8: 1
A9: EC2 | B9: =VLOOKUP(A9,tmat,2,FALSE) -> Espiga para Cruceta de Madera, L=8" Rosca 1-3/8", Φ = 3/4" | C9: C/U | D9: 1 | E9: 0
A10: CC2 | B10: =VLOOKUP(A10,tmat,2,FALSE) -> Conector de Compresión YC 25A25 (1/0-1/0) | C10: C/U | D10: 1 | E10: 1
A11: GT4 | B11: =VLOOKUP(A11,tmat,2,FALSE) -> Grapa Terminal tipo Recto para Conductor (1/0 - 4/0) | C11: C/U | D11: 1 | E11: 1
A12: PM1 | B12: =VLOOKUP(A12,tmat,2,FALSE) -> Perno de Máquina de 5/8" x 8" | C12: C/U | D12: 1 | E12: 1
A13: PM4 | B13: =VLOOKUP(A13,tmat,2,FALSE) -> Perno de Máquina de 5/8" x 14" | C13: C/U | D13: 1 | E13: 1
... A18: VAP2 | B18: =VLOOKUP(A18,tmat,2,FALSE) -> Varilla de Armar Preformado para Cable ASCR # 1/0 AWG | C18: C/U | D18: 1 | E18: 1

Sheet A-I-8
A1: COD. ENEE | B1: Materiales | C1: Unidad | D1: 34.5 | E1: 13.8
A2: AE1 | B2: =VLOOKUP(A2,tmat,2,FALSE) -> Aislador de Espiga ANSI C 55-4 | C2: C/U | D2: 0 | E2: 2
A3: AE2 | B3: =VLOOKUP(A3,tmat,2,FALSE) -> Aislador de Espiga ANSI C 56-3 | C3: C/U | D3: 2 | E3: 0
A4: AS2 | B4: =VLOOKUP(A4,tmat,2,FALSE) -> Aislador de Suspensión ANSI C 52-9 | C4: C/U | D4: 3 | E4: 2
A5: AA1 | B5: =VLOOKUP(A5,tmat,2,FALSE) -> Alambre de Amarre N° 6 | C5: Pie | D5: 10 | E5: 10
A6: AR1 | B6: =VLOOKUP(A6,tmat,2,FALSE) -> Arandela Cuadrada 3/16" x 2-1/4" x 2-1/4", Ø=11/16" | C6: C/U | D6: 2 | E6: 2
A7: CC2 | B7: =VLOOKUP(A7,tmat,2,FALSE) -> Conector de Compresión YC 25A25 (1/0-1/0) | C7: C/U | D7: 1 | E7: 1
A8: EPC | B8: =VLOOKUP(A8,tmat,2,FALSE) -> Espiga para Punta de Poste tipo Escuadra, 34.5 KV, L=21" Rosca 1-3/8" | C8: C/U | D8: 2 | E8: 0
A9: EP1 | B9: =VLOOKUP(A9,tmat,2,FALSE) -> Espiga Punta de Poste tipo Recta, 13.8 KV, L=18" Rosca 1" | C9: C/U | D9: 0 | E9: 2
A10: GT4 | B10: =VLOOKUP(A10,tmat,2,FALSE) -> Grapa Terminal tipo Recto para Conductor (1/0 - 4/0) | C10: C/U | D10: 1 | E10: 1
A11: PM3 | B11: =VLOOKUP(A11,tmat,2,FALSE) -> Perno de Máquina de 5/8" x 12" | C11: C/U | D11: 2 | E11: 2
A12: PRC1 | B12: =VLOOKUP(A12,tmat,2,FALSE) -> Perno de Rosca Corrida 5/8" x 12" | C12: C/U | D12: 1 | E12: 1
A13: TO1 | B13: =VLOOKUP(A13,tmat,2,FALSE) -> Tuerca de Ojo de 5/8" | C13: C/U | D13: 1 | E13: 1
A14: VAP2 | B14: =VLOOKUP(A14,tmat,2,FALSE) -> Varilla de Armar Preformado para Cable ASCR # 1/0 AWG | C14: C/U | D14: 1 | E14: 1

Sheet A-I-8V
A1: COD. ENEE | B1: Materiales | C1: Unidad | D1: 34.5 | E1: 13.8
A2: AE1 | B2: =VLOOKUP(A2,tmat,2,FALSE) -> Aislador de Espiga ANSI C 55-4 | C2: C/U | D2: 0 | E2: 2
A3: AE2 | B3: =VLOOKUP(A3,tmat,2,FALSE) -> Aislador de Espiga ANSI C 56-3 | C3: C/U | D3: 2 | E3: 0
A4: AS2 | B4: =VLOOKUP(A4,tmat,2,FALSE) -> Aislador de Suspensión ANSI C 52-9 | C4: C/U | D4: 3 | E4: 2
A5: AA1 | B5: =VLOOKUP(A5,tmat,2,FALSE) -> Alambre de Amarre N° 6 | C5: Pie | D5: 10 | E5: 10
A6: AR1 | B6: =VLOOKUP(A6,tmat,2,FALSE) -> Arandela Cuadrada 3/16" x 2-1/4" x 2-1/4", Ø=11/16" | C6: C/U | D6: 14 | E6: 14
A7: CC2 | B7: =VLOOKUP(A7,tmat,2,FALSE) -> Conector de Compresión YC 25A25 (1/0-1/0) | C7: C/U | D7: 1 | E7: 1
A8: CR3 | B8: =VLOOKUP(A8,tmat,2,FALSE) -> Crucete de Madera Curada de 4" x 5" x 96" /Voladizo | C8: C/U | D8: 2 | E8: 2
A9: EC1 | B9: =VLOOKUP(A9,tmat,2,FALSE) -> Espiga para Cruceta de Madera, L=6" Rosca 1", Φ = 3/4" | C9: C/U | D9: 0 | E9: 2
A10: EC2 | B10: =VLOOKUP(A10,tmat,2,FALSE) -> Espiga para Cruceta de Madera, L=8" Rosca 1-3/8", Φ = 3/4" | C10: C/U | D10: 2 | E10: 0
A11: GT4 | B11: =VLOOKUP(A11,tmat,2,FALSE) -> Grapa Terminal tipo Recto para Conductor (1/0 - 4/0) | C11: C/U | D11: 1 | E11: 1
A12: PLE | B12: =VLOOKUP(A12,tmat,2,FALSE) -> Pletina Espaciadora para Crucete Madera 1/2" x 4" x 24" | C12: C/U | D12: 2 | E12: 0
A13: PM1 | B13: =VLOOKUP(A13,tmat,2,FALSE) -> Perno de Máquina de 5/8" x 8" | C13: C/U | D13: 4 | E13: 4
... A19: VAP2 | B19: =VLOOKUP(A19,tmat,2,FALSE) -> Varilla de Armar Preformado para Cable ASCR # 1/0 AWG | C19: C/U | D19: 1 | E19: 1

Sheet A-I-9
A1: COD. ENEE | B1: Materiales | C1: Unidad | D1: 34.5 | E1: 13.8
A2: AE1 | B2: =VLOOKUP(A2,tmat,2,FALSE) -> Aislador de Espiga ANSI C 55-4 | C2: C/U | D2: 0 | E2: 1
A3: AE2 | B3: =VLOOKUP(A3,tmat,2,FALSE) -> Aislador de Espiga ANSI C 56-3 | C3: C/U | D3: 1 | E3: 0
A4: AS2 | B4: =VLOOKUP(A4,tmat,2,FALSE) -> Aislador de Suspensión ANSI C 52-9 | C4: C/U | D4: 9 | E4: 6
A5: AA1 | B5: =VLOOKUP(A5,tmat,2,FALSE) -> Alambre de Amarre N° 6 | C5: Pie | D5: 5 | E5: 5
A6: AR1 | B6: =VLOOKUP(A6,tmat,2,FALSE) -> Arandela Cuadrada 3/16" x 2-1/4" x 2-1/4", Ø=11/16" | C6: C/U | D6: 6 | E6: 6
A7: CC2 | B7: =VLOOKUP(A7,tmat,2,FALSE) -> Conector de Compresión YC 25A25 (1/0-1/0) | C7: C/U | D7: 2 | E7: 2
A8: EP2 | B8: =VLOOKUP(A8,tmat,2,FALSE) -> Espiga Punta de Poste tipo Recta, 34.5 KV, L=20" Rosca 1-3/8" | C8: C/U | D8: 1 | E8: 0
A9: EP1 | B9: =VLOOKUP(A9,tmat,2,FALSE) -> Espiga Punta de Poste tipo Recta, 13.8 KV, L=18" Rosca 1" | C9: C/U | D9: 0 | E9: 1
A10: GT4 | B10: =VLOOKUP(A10,tmat,2,FALSE) -> Grapa Terminal tipo Recto para Conductor (1/0 - 4/0) | C10: C/U | D10: 3 | E10: 3
A11: PM2 | B11: =VLOOKUP(A11,tmat,2,FALSE) -> Perno de Máquina de 5/8" x 10" | C11: C/U | D11: 2 | E11: 2
A12: PRC1 | B12: =VLOOKUP(A12,tmat,2,FALSE) -> Perno de Rosca Corrida 5/8" x 12" | C12: C/U | D12: 2 | E12: 2
A13: TO1 | B13: =VLOOKUP(A13,tmat,2,FALSE) -> Tuerca de Ojo de 5/8" | C13: C/U | D13: 3 | E13: 3

Sheet A-I-9V
A1: COD. ENEE | B1: Materiales | C1: Unidad | D1: 34.5 | E1: 13.8
A2: AE1 | B2: =VLOOKUP(A2,tmat,2,FALSE) -> Aislador de Espiga ANSI C 55-4 | C2: C/U | D2: 0 | E2: 1
A3: AE2 | B3: =VLOOKUP(A3,tmat,2,FALSE) -> Aislador de Espiga ANSI C 56-3 | C3: C/U | D3: 1 | E3: 0
A4: AS2 | B4: =VLOOKUP(A4,tmat,2,FALSE) -> Aislador de Suspensión ANSI C 52-9 | C4: C/U | D4: 9 | E4: 6
A5: AA1 | B5: =VLOOKUP(A5,tmat,2,FALSE) -> Alambre de Amarre N° 6 | C5: Pie | D5: 5 | E5: 5
A6: AR1 | B6: =VLOOKUP(A6,tmat,2,FALSE) -> Arandela Cuadrada 3/16" x 2-1/4" x 2-1/4", Ø=11/16" | C6: C/U | D6: 14 | E6: 14
A7: CC2 | B7: =VLOOKUP(A7,tmat,2,FALSE) -> Conector de Compresión YC 25A25 (1/0-1/0) | C7: C/U | D7: 2 | E7: 2
A8: CR3 | B8: =VLOOKUP(A8,tmat,2,FALSE) -> Crucete de Madera Curada de 4" x 5" x 96" /Voladizo | C8: C/U | D8: 2 | E8: 2
A9: EC1 | B9: =VLOOKUP(A9,tmat,2,FALSE) -> Espiga para Cruceta de Madera, L=6" Rosca 1", Φ = 3/4" | C9: C/U | D9: 0 | E9: 1
A10: EC2 | B10: =VLOOKUP(A10,tmat,2,FALSE) -> Espiga para Cruceta de Madera, L=8" Rosca 1-3/8", Φ = 3/4" | C10: C/U | D10: 1 | E10: 0
A11: GT4 | B11: =VLOOKUP(A11,tmat,2,FALSE) -> Grapa Terminal tipo Recto para Conductor (1/0 - 4/0) | C11: C/U | D11: 3 | E11: 3
A12: PM1 | B12: =VLOOKUP(A12,tmat,2,FALSE) -> Perno de Máquina de 5/8" x 8" | C12: C/U | D12: 2 | E12: 2
A13: PRC1 | B13: =VLOOKUP(A13,tmat,2,FALSE) -> Perno de Rosca Corrida 5/8" x 12" | C13: C/U | D13: 1 | E13: 1
... A17: TO1 | B17: =VLOOKUP(A17,tmat,2,FALSE) -> Tuerca de Ojo de 5/8" | C17: C/U | D17: 3 | E17: 3

Sheet A-II-1
A1: COD. ENEE | B1: Materiales | C1: Unidad | D1: 34.5 | E1: 13.8
A2: PC | B2: =VLOOKUP(A2,tmat,2,FALSE) -> Perno de Carroceria 3/8" x 5" | C2: C/U | D2: 2 | E2: 2
A3: CR2 | B3: =VLOOKUP(A3,tmat,2,FALSE) -> Crucete de Madera Curada de 4" x 5" x 96" | C3: C/U | D3: 1 | E3: 1
A4: TP | B4: =VLOOKUP(A4,tmat,2,FALSE) -> Tirante de Pletina de 1/4" x 1-1/4" x 30" | C4: C/U | D4: 2 | E4: 2
A5: PM10 | B5: =VLOOKUP(A5,tmat,2,FALSE) -> Perno de Máquina de 1/2" x 10" | C5: C/U | D5: 1 | E5: 1
A6: AA1 | B6: =VLOOKUP(A6,tmat,2,FALSE) -> Alambre de Amarre N° 6 | C6: Pie | D6: 2 | E6: 2
A7: AE2 | B7: =VLOOKUP(A7,tmat,2,FALSE) -> Aislador de Espiga ANSI C 56-3 | C7: C/U | D7: 2 | E7: 0
A8: AE1 | B8: =VLOOKUP(A8,tmat,2,FALSE) -> Aislador de Espiga ANSI C 55-4 | C8: C/U | D8: 0 | E8: 2
A9: VAP2 | B9: =VLOOKUP(A9,tmat,2,FALSE) -> Varilla de Armar Preformado para Cable ASCR # 1/0 AWG | C9: C/U | D9: 2 | E9: 2
A10: AR1 | B10: =VLOOKUP(A10,tmat,2,FALSE) -> Arandela Cuadrada 3/16" x 2-1/4" x 2-1/4", Ø=11/16" | C10: C/U | D10: 2 | E10: 2
A11: EC1 | B11: =VLOOKUP(A11,tmat,2,FALSE) -> Espiga para Cruceta de Madera, L=6" Rosca 1", Φ = 3/4" | C11: C/U | D11: 2 | E11: 0
A12: EC2 | B12: =VLOOKUP(A12,tmat,2,FALSE) -> Espiga para Cruceta de Madera, L=8" Rosca 1-3/8", Φ = 3/4" | C12: C/U | D12: 0 | E12: 2
A13: PM4 | B13: =VLOOKUP(A13,tmat,2,FALSE) -> Perno de Máquina de 5/8" x 14" | C13: C/U | D13: 1 | E13: 1

Sheet A-II-1V
A1: COD. ENEE | B1: Materiales | C1: Unidad | D1: 34.5 | E1: 13.8
A2: AR1 | B2: =VLOOKUP(A2,tmat,2,FALSE) -> Arandela Cuadrada 3/16" x 2-1/4" x 2-1/4", Ø=11/16" | C2: C/U | D2: 3 | E2: 3
A3: AA1 | B3: =VLOOKUP(A3,tmat,2,FALSE) -> Alambre de Amarre N° 6 | C3: Pie | D3: 20 | E3: 20
A4: AE2 | B4: =VLOOKUP(A4,tmat,2,FALSE) -> Aislador de Espiga ANSI C 56-3 | C4: C/U | D4: 2 | E4: 0
A5: AE1 | B5: =VLOOKUP(A5,tmat,2,FALSE) -> Aislador de Espiga ANSI C 55-4 | C5: C/U | D5: 0 | E5: 2
A6: VAP2 | B6: =VLOOKUP(A6,tmat,2,FALSE) -> Varilla de Armar Preformado para Cable ASCR # 1/0 AWG | C6: C/U | D6: 2 | E6: 2
A7: PM1 | B7: =VLOOKUP(A7,tmat,2,FALSE) -> Perno de Máquina de 5/8" x 8" | C7: C/U | D7: 1 | E7: 1
A8: PM4 | B8: =VLOOKUP(A8,tmat,2,FALSE) -> Perno de Máquina de 5/8" x 14" | C8: C/U | D8: 1 | E8: 1
A9: CR3 | B9: =VLOOKUP(A9,tmat,2,FALSE) -> Crucete de Madera Curada de 4" x 5" x 96" /Voladizo | C9: C/U | D9: 1 | E9: 1
A10: PAN1 | B10: =VLOOKUP(A10,tmat,2,FALSE) -> Puntal Angular de 60", 1-3/4" x 1-3/4" x 3/16" | C10: C/U | D10: 1 | E10: 1
A11: PM10 | B11: =VLOOKUP(A11,tmat,2,FALSE) -> Perno de Máquina de 1/2" x 10" | C11: C/U | D11: 1 | E11: 1
A12: EC1 | B12: =VLOOKUP(A12,tmat,2,FALSE) -> Espiga para Cruceta de Madera, L=6" Rosca 1", Φ = 3/4" | C12: C/U | D12: 2 | E12: 0
A13: EC2 | B13: =VLOOKUP(A13,tmat,2,FALSE) -> Espiga para Cruceta de Madera, L=8" Rosca 1-3/8", Φ = 3/4" | C13: C/U | D13: 0 | E13: 2

Sheet A-II-2
A1: COD. ENEE | B1: Materiales | C1: Unidad | D1: 34.5 | E1: 13.8
A2: AR1 | B2: =VLOOKUP(A2,tmat,2,FALSE) -> Arandela Cuadrada 3/16" x 2-1/4" x 2-1/4", Ø=11/16" | C2: C/U | D2: 4 | E2: 4
A3: PC | B3: =VLOOKUP(A3,tmat,2,FALSE) -> Perno de Carroceria 3/8" x 5" | C3: C/U | D3: 4 | E3: 4
A4: CR2 | B4: =VLOOKUP(A4,tmat,2,FALSE) -> Crucete de Madera Curada de 4" x 5" x 96" | C4: C/U | D4: 2 | E4: 2
A5: TP | B5: =VLOOKUP(A5,tmat,2,FALSE) -> Tirante de Pletina de 1/4" x 1-1/4" x 30" | C5: C/U | D5: 4 | E5: 4
A6: PM10 | B6: =VLOOKUP(A6,tmat,2,FALSE) -> Perno de Máquina de 1/2" x 10" | C6: C/U | D6: 2 | E6: 2
A7: AA1 | B7: =VLOOKUP(A7,tmat,2,FALSE) -> Alambre de Amarre N° 6 | C7: Pie | D7: 20 | E7: 20
A8: VAP2 | B8: =VLOOKUP(A8,tmat,2,FALSE) -> Varilla de Armar Preformado para Cable ASCR # 1/0 AWG | C8: C/U | D8: 2 | E8: 2
A9: PM10 | B9: =VLOOKUP(A9,tmat,2,FALSE) -> Perno de Máquina de 1/2" x 10" | C9: C/U | D9: 4 | E9: 0
A10: EC1 | B10: =VLOOKUP(A10,tmat,2,FALSE) -> Espiga para Cruceta de Madera, L=6" Rosca 1", Φ = 3/4" | C10: C/U | D10: 4 | E10: 0
A11: EC2 | B11: =VLOOKUP(A11,tmat,2,FALSE) -> Espiga para Cruceta de Madera, L=8" Rosca 1-3/8", Φ = 3/4" | C11: C/U | D11: 0 | E11: 4
A12: PLE | B12: =VLOOKUP(A12,tmat,2,FALSE) -> Pletina Espaciadora para Crucete Madera 1/2" x 4" x 24" | C12: C/U | D12: 3 | E12: 3
A13: PRC5 | B13: =VLOOKUP(A13,tmat,2,FALSE) -> Perno de Rosca Corrida 5/8" x 20" | C13: C/U | D13: 3 | E13: 3
... A15: AE1 | B15: =VLOOKUP(A15,tmat,2,FALSE) -> Aislador de Espiga ANSI C 55-4 | C15: C/U | D15: 0 | E15: 4

Sheet A-II-2V
A1: COD. ENEE | B1: Materiales | C1: Unidad | D1: 34.5 | E1: 13.8
A2: AA1 | B2: =VLOOKUP(A2,tmat,2,FALSE) -> Alambre de Amarre N° 6 | C2: Pie | D2: 2 | E2: 2
A3: AE2 | B3: =VLOOKUP(A3,tmat,2,FALSE) -> Aislador de Espiga ANSI C 56-3 | C3: C/U | D3: 4 | E3: 0
A4: AE1 | B4: =VLOOKUP(A4,tmat,2,FALSE) -> Aislador de Espiga ANSI C 55-4 | C4: C/U | D4: 0 | E4: 4
A5: VAP2 | B5: =VLOOKUP(A5,tmat,2,FALSE) -> Varilla de Armar Preformado para Cable ASCR # 1/0 AWG | C5: C/U | D5: 2 | E5: 2
A6: AR1 | B6: =VLOOKUP(A6,tmat,2,FALSE) -> Arandela Cuadrada 3/16" x 2-1/4" x 2-1/4", Ø=11/16" | C6: C/U | D6: 12 | E6: 12
A7: PM1 | B7: =VLOOKUP(A7,tmat,2,FALSE) -> Perno de Máquina de 5/8" x 8" | C7: C/U | D7: 2 | E7: 2
A8: PAN1 | B8: =VLOOKUP(A8,tmat,2,FALSE) -> Puntal Angular de 60", 1-3/4" x 1-3/4" x 3/16" | C8: C/U | D8: 2 | E8: 2
A9: EC1 | B9: =VLOOKUP(A9,tmat,2,FALSE) -> Espiga para Cruceta de Madera, L=6" Rosca 1", Φ = 3/4" | C9: C/U | D9: 4 | E9: 0
A10: EC2 | B10: =VLOOKUP(A10,tmat,2,FALSE) -> Espiga para Cruceta de Madera, L=8" Rosca 1-3/8", Φ = 3/4" | C10: C/U | D10: 0 | E10: 4
A11: PLE | B11: =VLOOKUP(A11,tmat,2,FALSE) -> Pletina Espaciadora para Crucete Madera 1/2" x 4" x 24" | C11: C/U | D11: 2 | E11: 2
A12: CR3 | B12: =VLOOKUP(A12,tmat,2,FALSE) -> Crucete de Madera Curada de 4" x 5" x 96" /Voladizo | C12: C/U | D12: 2 | E12: 2
A13: PM10 | B13: =VLOOKUP(A13,tmat,2,FALSE) -> Perno de Máquina de 1/2" x 10" | C13: C/U | D13: 2 | E13: 2
A14: PRC5 | B14: =VLOOKUP(A14,tmat,2,FALSE) -> Perno de Rosca Corrida 5/8" x 20" | C14: C/U | D14: 3 | E14: 3

Sheet A-II-3
A1: COD. ENEE | B1: Materiales | C1: Unidad | D1: 34.5 | E1: 13.8
A2: AS2 | B2: =VLOOKUP(A2,tmat,2,FALSE) -> Aislador de Suspensión ANSI C 52-9 | C2: C/U | D2: 6 | E2: 4
A3: AR1 | B3: =VLOOKUP(A3,tmat,2,FALSE) -> Arandela Cuadrada 3/16" x 2-1/4" x 2-1/4", Ø=11/16" | C3: C/U | D3: 2 | E3: 2
A4: PRC1 | B4: =VLOOKUP(A4,tmat,2,FALSE) -> Perno de Rosca Corrida 5/8" x 12" | C4: C/U | D4: 2 | E4: 2
A5: GS1 | B5: =VLOOKUP(A5,tmat,2,FALSE) -> Grapa de Suspensión para Conductor (1/0- 477) | C5: C/U | D5: 2 | E5: 2
A6: VAP2 | B6: =VLOOKUP(A6,tmat,2,FALSE) -> Varilla de Armar Preformado para Cable ASCR # 1/0 AWG | C6: C/U | D6: 2 | E6: 2
A7: TO1 | B7: =VLOOKUP(A7,tmat,2,FALSE) -> Tuerca de Ojo de 5/8" | C7: C/U | D7: 2 | E7: 2

Sheet A-II-4
A1: COD. ENEE | B1: Materiales | C1: Unidad | D1: 34.5 | E1: 13.8
A2: AR1 | B2: =VLOOKUP(A2,tmat,2,FALSE) -> Arandela Cuadrada 3/16" x 2-1/4" x 2-1/4", Ø=11/16" | C2: C/U | D2: 10 | E2: 10
A3: PC | B3: =VLOOKUP(A3,tmat,2,FALSE) -> Perno de Carroceria 3/8" x 5" | C3: C/U | D3: 4 | E3: 4
A4: AS2 | B4: =VLOOKUP(A4,tmat,2,FALSE) -> Aislador de Suspensión ANSI C 52-9 | C4: C/U | D4: 6 | E4: 4
A5: CR2 | B5: =VLOOKUP(A5,tmat,2,FALSE) -> Crucete de Madera Curada de 4" x 5" x 96" | C5: C/U | D5: 2 | E5: 2
A6: GT4 | B6: =VLOOKUP(A6,tmat,2,FALSE) -> Grapa Terminal tipo Recto para Conductor (1/0 - 4/0) | C6: C/U | D6: 2 | E6: 2
A7: TP | B7: =VLOOKUP(A7,tmat,2,FALSE) -> Tirante de Pletina de 1/4" x 1-1/4" x 30" | C7: C/U | D7: 4 | E7: 4
A8: PM10 | B8: =VLOOKUP(A8,tmat,2,FALSE) -> Perno de Máquina de 1/2" x 10" | C8: C/U | D8: 2 | E8: 2
A9: PRC5 | B9: =VLOOKUP(A9,tmat,2,FALSE) -> Perno de Rosca Corrida 5/8" x 20" | C9: C/U | D9: 3 | E9: 3
A10: TO1 | B10: =VLOOKUP(A10,tmat,2,FALSE) -> Tuerca de Ojo de 5/8" | C10: C/U | D10: 2 | E10: 2

Sheet A-II-4A
A1: COD. ENEE | B1: Materiales | C1: Unidad | D1: 34.5 | E1: 13.8
A2: AS2 | B2: =VLOOKUP(A2,tmat,2,FALSE) -> Aislador de Suspensión ANSI C 52-9 | C2: C/U | D2: 6 | E2: 4
A3: AA1 | B3: =VLOOKUP(A3,tmat,2,FALSE) -> Alambre de Amarre N° 6 | C3: Pie | D3: 10 | E3: 10
A4: EC1 | B4: =VLOOKUP(A4,tmat,2,FALSE) -> Espiga para Cruceta de Madera, L=6" Rosca 1", Φ = 3/4" | C4: C/U | D4: 2 | E4: 0
A5: EC2 | B5: =VLOOKUP(A5,tmat,2,FALSE) -> Espiga para Cruceta de Madera, L=8" Rosca 1-3/8", Φ = 3/4" | C5: C/U | D5: 0 | E5: 2
A6: GT4 | B6: =VLOOKUP(A6,tmat,2,FALSE) -> Grapa Terminal tipo Recto para Conductor (1/0 - 4/0) | C6: C/U | D6: 2 | E6: 2
A7: TO1 | B7: =VLOOKUP(A7,tmat,2,FALSE) -> Tuerca de Ojo de 5/8" | C7: C/U | D7: 2 | E7: 2
A8: AE2 | B8: =VLOOKUP(A8,tmat,2,FALSE) -> Aislador de Espiga ANSI C 56-3 | C8: C/U | D8: 2 | E8: 0
A9: AE1 | B9: =VLOOKUP(A9,tmat,2,FALSE) -> Aislador de Espiga ANSI C 55-4 | C9: C/U | D9: 0 | E9: 2
A10: CC2 | B10: =VLOOKUP(A10,tmat,2,FALSE) -> Conector de Compresión YC 25A25 (1/0-1/0) | C10: C/U | D10: 2 | E10: 2

Sheet A-II-4D
A1: COD. ENEE | B1: Materiales | C1: Unidad | D1: 34.5 | E1: 13.8
A2: AR1 | B2: =VLOOKUP(A2,tmat,2,FALSE) -> Arandela Cuadrada 3/16" x 2-1/4" x 2-1/4", Ø=11/16" | C2: C/U | D2: 10 | E2: 10
A3: PC | B3: =VLOOKUP(A3,tmat,2,FALSE) -> Perno de Carroceria 3/8" x 5" | C3: C/U | D3: 4 | E3: 4
A4: AS2 | B4: =VLOOKUP(A4,tmat,2,FALSE) -> Aislador de Suspensión ANSI C 52-9 | C4: C/U | D4: 6 | E4: 4
A5: CR2 | B5: =VLOOKUP(A5,tmat,2,FALSE) -> Crucete de Madera Curada de 4" x 5" x 96" | C5: C/U | D5: 2 | E5: 2
A6: TP | B6: =VLOOKUP(A6,tmat,2,FALSE) -> Tirante de Pletina de 1/4" x 1-1/4" x 30" | C6: C/U | D6: 4 | E6: 4
A7: PM10 | B7: =VLOOKUP(A7,tmat,2,FALSE) -> Perno de Máquina de 1/2" x 10" | C7: C/U | D7: 2 | E7: 2
A8: TO1 | B8: =VLOOKUP(A8,tmat,2,FALSE) -> Tuerca de Ojo de 5/8" | C8: C/U | D8: 2 | E8: 2
A9: AA1 | B9: =VLOOKUP(A9,tmat,2,FALSE) -> Alambre de Amarre N° 6 | C9: Pie | D9: 10 | E9: 10
A10: EC1 | B10: =VLOOKUP(A10,tmat,2,FALSE) -> Espiga para Cruceta de Madera, L=6" Rosca 1", Φ = 3/4" | C10: C/U | D10: 2 | E10: 0
A11: EC2 | B11: =VLOOKUP(A11,tmat,2,FALSE) -> Espiga para Cruceta de Madera, L=8" Rosca 1-3/8", Φ = 3/4" | C11: C/U | D11: 0 | E11: 2
A12: PRC5 | B12: =VLOOKUP(A12,tmat,2,FALSE) -> Perno de Rosca Corrida 5/8" x 20" | C12: C/U | D12: 3 | E12: 3
A13: GT4 | B13: =VLOOKUP(A13,tmat,2,FALSE) -> Grapa Terminal tipo Recto para Conductor (1/0 - 4/0) | C13: C/U | D13: 2 | E13: 2
... A16: CC2 | B16: =VLOOKUP(A16,tmat,2,FALSE) -> Conector de Compresión YC 25A25 (1/0-1/0) | C16: C/U | D16: 2 | E16: 2

Sheet A-II-4E
A1: COD. ENEE | B1: Materiales | C1: Unidad | D1: 34.5 | E1: 13.8
A2: AR1 | B2: =VLOOKUP(A2,tmat,2,FALSE) -> Arandela Cuadrada 3/16" x 2-1/4" x 2-1/4", Ø=11/16" | C2: C/U | D2: 10 | E2: 10
A3: PC | B3: =VLOOKUP(A3,tmat,2,FALSE) -> Perno de Carroceria 3/8" x 5" | C3: C/U | D3: 4 | E3: 4
A4: AS2 | B4: =VLOOKUP(A4,tmat,2,FALSE) -> Aislador de Suspensión ANSI C 52-9 | C4: C/U | D4: 6 | E4: 4
A5: CR2 | B5: =VLOOKUP(A5,tmat,2,FALSE) -> Crucete de Madera Curada de 4" x 5" x 96" | C5: C/U | D5: 2 | E5: 2
A6: TP | B6: =VLOOKUP(A6,tmat,2,FALSE) -> Tirante de Pletina de 1/4" x 1-1/4" x 30" | C6: C/U | D6: 4 | E6: 4
A7: PM10 | B7: =VLOOKUP(A7,tmat,2,FALSE) -> Perno de Máquina de 1/2" x 10" | C7: C/U | D7: 2 | E7: 2
A8: TO1 | B8: =VLOOKUP(A8,tmat,2,FALSE) -> Tuerca de Ojo de 5/8" | C8: C/U | D8: 2 | E8: 2
A9: AA1 | B9: =VLOOKUP(A9,tmat,2,FALSE) -> Alambre de Amarre N° 6 | C9: Pie | D9: 5 | E9: 5
A10: EC1 | B10: =VLOOKUP(A10,tmat,2,FALSE) -> Espiga para Cruceta de Madera, L=6" Rosca 1", Φ = 3/4" | C10: C/U | D10: 1 | E10: 0
A11: EC2 | B11: =VLOOKUP(A11,tmat,2,FALSE) -> Espiga para Cruceta de Madera, L=8" Rosca 1-3/8", Φ = 3/4" | C11: C/U | D11: 0 | E11: 1
A12: PRC5 | B12: =VLOOKUP(A12,tmat,2,FALSE) -> Perno de Rosca Corrida 5/8" x 20" | C12: C/U | D12: 3 | E12: 3
A13: GT4 | B13: =VLOOKUP(A13,tmat,2,FALSE) -> Grapa Terminal tipo Recto para Conductor (1/0 - 4/0) | C13: C/U | D13: 2 | E13: 2
... A16: CC2 | B16: =VLOOKUP(A16,tmat,2,FALSE) -> Conector de Compresión YC 25A25 (1/0-1/0) | C16: C/U | D16: 2 | E16: 2

Sheet A-II-4V
A1: COD. ENEE | B1: Materiales | C1: Unidad | D1: 34.5 | E1: 13.8
A2: AR1 | B2: =VLOOKUP(A2,tmat,2,FALSE) -> Arandela Cuadrada 3/16" x 2-1/4" x 2-1/4", Ø=11/16" | C2: C/U | D2: 12 | E2: 12
A3: AS2 | B3: =VLOOKUP(A3,tmat,2,FALSE) -> Aislador de Suspensión ANSI C 52-9 | C3: C/U | D3: 6 | E3: 4
A4: GT4 | B4: =VLOOKUP(A4,tmat,2,FALSE) -> Grapa Terminal tipo Recto para Conductor (1/0 - 4/0) | C4: C/U | D4: 2 | E4: 2
A5: TO1 | B5: =VLOOKUP(A5,tmat,2,FALSE) -> Tuerca de Ojo de 5/8" | C5: C/U | D5: 2 | E5: 2
A6: PM1 | B6: =VLOOKUP(A6,tmat,2,FALSE) -> Perno de Máquina de 5/8" x 8" | C6: C/U | D6: 2 | E6: 2
A7: PAN1 | B7: =VLOOKUP(A7,tmat,2,FALSE) -> Puntal Angular de 60", 1-3/4" x 1-3/4" x 3/16" | C7: C/U | D7: 2 | E7: 2
A8: CR3 | B8: =VLOOKUP(A8,tmat,2,FALSE) -> Crucete de Madera Curada de 4" x 5" x 96" /Voladizo | C8: C/U | D8: 2 | E8: 2
A9: PM10 | B9: =VLOOKUP(A9,tmat,2,FALSE) -> Perno de Máquina de 1/2" x 10" | C9: C/U | D9: 2 | E9: 2
A10: PRC5 | B10: =VLOOKUP(A10,tmat,2,FALSE) -> Perno de Rosca Corrida 5/8" x 20" | C10: C/U | D10: 3 | E10: 3

Sheet A-II-5
A1: COD. ENEE | B1: Materiales | C1: Unidad | D1: 34.5 | E1: 13.8
A2: AR1 | B2: =VLOOKUP(A2,tmat,2,FALSE) -> Arandela Cuadrada 3/16" x 2-1/4" x 2-1/4", Ø=11/16" | C2: C/U | D2: 4 | E2: 4
A3: PC | B3: =VLOOKUP(A3,tmat,2,FALSE) -> Perno de Carroceria 3/8" x 5" | C3: C/U | D3: 4 | E3: 4
A4: AS2 | B4: =VLOOKUP(A4,tmat,2,FALSE) -> Aislador de Suspensión ANSI C 52-9 | C4: C/U | D4: 8 | E4: 8
A5: CR2 | B5: =VLOOKUP(A5,tmat,2,FALSE) -> Crucete de Madera Curada de 4" x 5" x 96" | C5: C/U | D5: 2 | E5: 2
A6: TP | B6: =VLOOKUP(A6,tmat,2,FALSE) -> Tirante de Pletina de 1/4" x 1-1/4" x 30" | C6: C/U | D6: 4 | E6: 4
A7: PM10 | B7: =VLOOKUP(A7,tmat,2,FALSE) -> Perno de Máquina de 1/2" x 10" | C7: C/U | D7: 2 | E7: 2
A8: TO1 | B8: =VLOOKUP(A8,tmat,2,FALSE) -> Tuerca de Ojo de 5/8" | C8: C/U | D8: 4 | E8: 4
A9: AA1 | B9: =VLOOKUP(A9,tmat,2,FALSE) -> Alambre de Amarre N° 6 | C9: Pie | D9: 20 | E9: 20
A10: EC1 | B10: =VLOOKUP(A10,tmat,2,FALSE) -> Espiga para Cruceta de Madera, L=6" Rosca 1", Φ = 3/4" | C10: C/U | D10: 2 | E10: 0
A11: EC2 | B11: =VLOOKUP(A11,tmat,2,FALSE) -> Espiga para Cruceta de Madera, L=8" Rosca 1-3/8", Φ = 3/4" | C11: C/U | D11: 0 | E11: 2
A12: PRC5 | B12: =VLOOKUP(A12,tmat,2,FALSE) -> Perno de Rosca Corrida 5/8" x 20" | C12: C/U | D12: 3 | E12: 3
A13: GT4 | B13: =VLOOKUP(A13,tmat,2,FALSE) -> Grapa Terminal tipo Recto para Conductor (1/0 - 4/0) | C13: C/U | D13: 4 | E13: 4
... A16: CC2 | B16: =VLOOKUP(A16,tmat,2,FALSE) -> Conector de Compresión YC 25A25 (1/0-1/0) | C16: C/U | D16: 2 | E16: 2

Sheet A-II-5V
A1: COD. ENEE | B1: Materiales | C1: Unidad | D1: 34.5 | E1: 13.8
A2: AR1 | B2: =VLOOKUP(A2,tmat,2,FALSE) -> Arandela Cuadrada 3/16" x 2-1/4" x 2-1/4", Ø=11/16" | C2: C/U | D2: 2 | E2: 2
A3: AS2 | B3: =VLOOKUP(A3,tmat,2,FALSE) -> Aislador de Suspensión ANSI C 52-9 | C3: C/U | D3: 12 | E3: 8
A4: GT4 | B4: =VLOOKUP(A4,tmat,2,FALSE) -> Grapa Terminal tipo Recto para Conductor (1/0 - 4/0) | C4: C/U | D4: 4 | E4: 4
A5: AA1 | B5: =VLOOKUP(A5,tmat,2,FALSE) -> Alambre de Amarre N° 6 | C5: Pie | D5: 10 | E5: 10
A6: AE2 | B6: =VLOOKUP(A6,tmat,2,FALSE) -> Aislador de Espiga ANSI C 56-3 | C6: C/U | D6: 2 | E6: 0
A7: AE1 | B7: =VLOOKUP(A7,tmat,2,FALSE) -> Aislador de Espiga ANSI C 55-4 | C7: C/U | D7: 0 | E7: 2
A8: PM1 | B8: =VLOOKUP(A8,tmat,2,FALSE) -> Perno de Máquina de 5/8" x 8" | C8: C/U | D8: 2 | E8: 2
A9: PAN1 | B9: =VLOOKUP(A9,tmat,2,FALSE) -> Puntal Angular de 60", 1-3/4" x 1-3/4" x 3/16" | C9: C/U | D9: 2 | E9: 2
A10: CR3 | B10: =VLOOKUP(A10,tmat,2,FALSE) -> Crucete de Madera Curada de 4" x 5" x 96" /Voladizo | C10: C/U | D10: 2 | E10: 2
A11: PM10 | B11: =VLOOKUP(A11,tmat,2,FALSE) -> Perno de Máquina de 1/2" x 10" | C11: C/U | D11: 2 | E11: 2
A12: TO1 | B12: =VLOOKUP(A12,tmat,2,FALSE) -> Tuerca de Ojo de 5/8" | C12: C/U | D12: 4 | E12: 4
A13: CC2 | B13: =VLOOKUP(A13,tmat,2,FALSE) -> Conector de Compresión YC 25A25 (1/0-1/0) | C13: C/U | D13: 2 | E13: 2
... A16: PRC5 | B16: =VLOOKUP(A16,tmat,2,FALSE) -> Perno de Rosca Corrida 5/8" x 20" | C16: C/U | D16: 2 | E16: 2

Sheet A-II-6
A1: COD. ENEE | B1: Materiales | C1: Unidad | D1: 34.5 | E1: 13.8
A2: AR1 | B2: =VLOOKUP(A2,tmat,2,FALSE) -> Arandela Cuadrada 3/16" x 2-1/4" x 2-1/4", Ø=11/16" | C2: C/U | D2: 20 | E2: 8
A3: PC | B3: =VLOOKUP(A3,tmat,2,FALSE) -> Perno de Carroceria 3/8" x 5" | C3: C/U | D3: 8 | E3: 8
A4: AS2 | B4: =VLOOKUP(A4,tmat,2,FALSE) -> Aislador de Suspensión ANSI C 52-9 | C4: C/U | D4: 12 | E4: 8
A5: CR2 | B5: =VLOOKUP(A5,tmat,2,FALSE) -> Crucete de Madera Curada de 4" x 5" x 96" | C5: C/U | D5: 4 | E5: 4
A6: TP | B6: =VLOOKUP(A6,tmat,2,FALSE) -> Tirante de Pletina de 1/4" x 1-1/4" x 30" | C6: C/U | D6: 8 | E6: 8
A7: PM10 | B7: =VLOOKUP(A7,tmat,2,FALSE) -> Perno de Máquina de 1/2" x 10" | C7: C/U | D7: 4 | E7: 4
A8: TO1 | B8: =VLOOKUP(A8,tmat,2,FALSE) -> Tuerca de Ojo de 5/8" | C8: C/U | D8: 4 | E8: 4
A9: AA1 | B9: =VLOOKUP(A9,tmat,2,FALSE) -> Alambre de Amarre N° 6 | C9: Pie | D9: 10 | E9: 20
A10: AE2 | B10: =VLOOKUP(A10,tmat,2,FALSE) -> Aislador de Espiga ANSI C 56-3 | C10: C/U | D10: 2 | E10: 0
A11: AE1 | B11: =VLOOKUP(A11,tmat,2,FALSE) -> Aislador de Espiga ANSI C 55-4 | C11: C/U | D11: 0 | E11: 2
A12: GT4 | B12: =VLOOKUP(A12,tmat,2,FALSE) -> Grapa Terminal tipo Recto para Conductor (1/0 - 4/0) | C12: C/U | D12: 4 | E12: 4
A13: CC2 | B13: =VLOOKUP(A13,tmat,2,FALSE) -> Conector de Compresión YC 25A25 (1/0-1/0) | C13: C/U | D13: 2 | E13: 2
... A16: PRC5 | B16: =VLOOKUP(A16,tmat,2,FALSE) -> Perno de Rosca Corrida 5/8" x 20" | C16: C/U | D16: 2 | E16: 2

Sheet A-II-6A
A1: COD. ENEE | B1: Materiales | C1: Unidad | D1: 34.5 | E1: 13.8
A2: AR1 | B2: =VLOOKUP(A2,tmat,2,FALSE) -> Arandela Cuadrada 3/16" x 2-1/4" x 2-1/4", Ø=11/16" | C2: C/U | D2: 20 | E2: 8
A3: PC | B3: =VLOOKUP(A3,tmat,2,FALSE) -> Perno de Carroceria 3/8" x 5" | C3: C/U | D3: 8 | E3: 8
A4: AS2 | B4: =VLOOKUP(A4,tmat,2,FALSE) -> Aislador de Suspensión ANSI C 52-9 | C4: C/U | D4: 15 | E4: 10
A5: CR2 | B5: =VLOOKUP(A5,tmat,2,FALSE) -> Crucete de Madera Curada de 4" x 5" x 96" | C5: C/U | D5: 4 | E5: 4
A6: TP | B6: =VLOOKUP(A6,tmat,2,FALSE) -> Tirante de Pletina de 1/4" x 1-1/4" x 30" | C6: C/U | D6: 8 | E6: 8
A7: PM10 | B7: =VLOOKUP(A7,tmat,2,FALSE) -> Perno de Máquina de 1/2" x 10" | C7: C/U | D7: 4 | E7: 4
A8: TO1 | B8: =VLOOKUP(A8,tmat,2,FALSE) -> Tuerca de Ojo de 5/8" | C8: C/U | D8: 5 | E8: 5
A9: AA1 | B9: =VLOOKUP(A9,tmat,2,FALSE) -> Alambre de Amarre N° 6 | C9: Pie | D9: 10 | E9: 20
A10: AE2 | B10: =VLOOKUP(A10,tmat,2,FALSE) -> Aislador de Espiga ANSI C 56-3 | C10: C/U | D10: 2 | E10: 0
A11: AE1 | B11: =VLOOKUP(A11,tmat,2,FALSE) -> Aislador de Espiga ANSI C 55-4 | C11: C/U | D11: 0 | E11: 2
A12: GT4 | B12: =VLOOKUP(A12,tmat,2,FALSE) -> Grapa Terminal tipo Recto para Conductor (1/0 - 4/0) | C12: C/U | D12: 5 | E12: 5
A13: CC2 | B13: =VLOOKUP(A13,tmat,2,FALSE) -> Conector de Compresión YC 25A25 (1/0-1/0) | C13: C/U | D13: 3 | E13: 3
... A16: PRC5 | B16: =VLOOKUP(A16,tmat,2,FALSE) -> Perno de Rosca Corrida 5/8" x 20" | C16: C/U | D16: 2 | E16: 2

Sheet A-II-6R
A1: COD. ENEE | B1: Materiales | C1: Unidad | D1: 34.5 | E1: 13.8
A2: AR1 | B2: =VLOOKUP(A2,tmat,2,FALSE) -> Arandela Cuadrada 3/16" x 2-1/4" x 2-1/4", Ø=11/16" | C2: C/U | D2: 8 | E2: 8
A3: AS2 | B3: =VLOOKUP(A3,tmat,2,FALSE) -> Aislador de Suspensión ANSI C 52-9 | C3: C/U | D3: 12 | E3: 8
A4: GT4 | B4: =VLOOKUP(A4,tmat,2,FALSE) -> Grapa Terminal tipo Recto para Conductor (1/0 - 4/0) | C4: C/U | D4: 4 | E4: 4
A5: PRC1 | B5: =VLOOKUP(A5,tmat,2,FALSE) -> Perno de Rosca Corrida 5/8" x 12" | C5: C/U | D5: 4 | E5: 4
A6: TO1 | B6: =VLOOKUP(A6,tmat,2,FALSE) -> Tuerca de Ojo de 5/8" | C6: C/U | D6: 4 | E6: 4
A7: CC2 | B7: =VLOOKUP(A7,tmat,2,FALSE) -> Conector de Compresión YC 25A25 (1/0-1/0) | C7: C/U | D7: 2 | E7: 2

Sheet A-II-7
A1: COD. ENEE | B1: Materiales | C1: Unidad | D1: 34.5 | E1: 13.8
A2: AR1 | B2: =VLOOKUP(A2,tmat,2,FALSE) -> Arandela Cuadrada 3/16" x 2-1/4" x 2-1/4", Ø=11/16" | C2: C/U | D2: 6 | E2: 6
A3: AS2 | B3: =VLOOKUP(A3,tmat,2,FALSE) -> Aislador de Suspensión ANSI C 52-9 | C3: C/U | D3: 6 | E3: 4
A4: CR2 | B4: =VLOOKUP(A4,tmat,2,FALSE) -> Crucete de Madera Curada de 4" x 5" x 96" | C4: C/U | D4: 2 | E4: 2
A5: TP | B5: =VLOOKUP(A5,tmat,2,FALSE) -> Tirante de Pletina de 1/4" x 1-1/4" x 30" | C5: C/U | D5: 4 | E5: 4
A6: PM10 | B6: =VLOOKUP(A6,tmat,2,FALSE) -> Perno de Máquina de 1/2" x 10" | C6: C/U | D6: 2 | E6: 2
A7: TO1 | B7: =VLOOKUP(A7,tmat,2,FALSE) -> Tuerca de Ojo de 5/8" | C7: C/U | D7: 2 | E7: 2
A8: AA1 | B8: =VLOOKUP(A8,tmat,2,FALSE) -> Alambre de Amarre N° 6 | C8: Pie | D8: 20 | E8: 20
A9: VAP2 | B9: =VLOOKUP(A9,tmat,2,FALSE) -> Varilla de Armar Preformado para Cable ASCR # 1/0 AWG | C9: C/U | D9: 2 | E9: 2
A10: PM1 | B10: =VLOOKUP(A10,tmat,2,FALSE) -> Perno de Máquina de 5/8" x 8" | C10: C/U | D10: 2 | E10: 2
A11: PAN1 | B11: =VLOOKUP(A11,tmat,2,FALSE) -> Puntal Angular de 60", 1-3/4" x 1-3/4" x 3/16" | C11: C/U | D11: 2 | E11: 2
A12: EC1 | B12: =VLOOKUP(A12,tmat,2,FALSE) -> Espiga para Cruceta de Madera, L=6" Rosca 1", Φ = 3/4" | C12: C/U | D12: 2 | E12: 0
A13: EC2 | B13: =VLOOKUP(A13,tmat,2,FALSE) -> Espiga para Cruceta de Madera, L=8" Rosca 1-3/8", Φ = 3/4" | C13: C/U | D13: 0 | E13: 2
... A21: PC | B21: =VLOOKUP(A21,tmat,2,FALSE) -> Perno de Carroceria 3/8" x 5" | C21: C/U | D21: 4 | E21: 4

Sheet A-II-7A
A1: COD. ENEE | B1: Materiales | C1: Unidad | D1: 34.5 | E1: 13.8
A2: AR1 | B2: =VLOOKUP(A2,tmat,2,FALSE) -> Arandela Cuadrada 3/16" x 2-1/4" x 2-1/4", Ø=11/16" | C2: C/U | D2: 4 | E2: 4
A3: AS2 | B3: =VLOOKUP(A3,tmat,2,FALSE) -> Aislador de Suspensión ANSI C 52-9 | C3: C/U | D3: 3 | E3: 2
A4: CR2 | B4: =VLOOKUP(A4,tmat,2,FALSE) -> Crucete de Madera Curada de 4" x 5" x 96" | C4: C/U | D4: 2 | E4: 2
A5: TP | B5: =VLOOKUP(A5,tmat,2,FALSE) -> Tirante de Pletina de 1/4" x 1-1/4" x 30" | C5: C/U | D5: 2 | E5: 2
A6: PM10 | B6: =VLOOKUP(A6,tmat,2,FALSE) -> Perno de Máquina de 1/2" x 10" | C6: C/U | D6: 1 | E6: 1
A7: TO1 | B7: =VLOOKUP(A7,tmat,2,FALSE) -> Tuerca de Ojo de 5/8" | C7: C/U | D7: 1 | E7: 1
A8: AA1 | B8: =VLOOKUP(A8,tmat,2,FALSE) -> Alambre de Amarre N° 6 | C8: Pie | D8: 10 | E8: 10
A9: VAP2 | B9: =VLOOKUP(A9,tmat,2,FALSE) -> Varilla de Armar Preformado para Cable ASCR # 1/0 AWG | C9: C/U | D9: 2 | E9: 2
A10: PM1 | B10: =VLOOKUP(A10,tmat,2,FALSE) -> Perno de Máquina de 5/8" x 8" | C10: C/U | D10: 1 | E10: 1
